Workbook
Name Lookup3: #REF!
Name Lookup3: #REF!
Name Lookup4: #REF!
Name Lookup4: #REF!
Name Lookup5: #REF!
Name Lookup5: #REF!
Name Lookup8: #REF!
Name Lookup8: #REF!
Name MY_FUNCTION1: LAMBDA(COUNTIF(#REF!,"P, GS, NS, AS")+COUNTIF(#REF!,"HFL")/2)
Name MY_FUNCTION1: LAMBDA(COUNTIF(#REF!,"P, GS, NS, AS")+COUNTIF(#REF!,"HFL")/2)

Sheet Anchors_Feb'26
O1: 28 | AB1: EMPLOYEE CONTRIBUTION | AE1: EMPLOYER CONTRIBUTION | AH1: DEDUCTIONS
A2: Sl.No. | B2: EMP ID | C2: DOJ | D2: Employee Name | E2: Department | F2: Bank A/c No | G2: IFSC | H2: UAN | I2: PAN | J2: ESI NO | K2: DOB | L2: Gender | M2: Bifurcation of Employees | N2: DOE | O2: Payable Days | P2: Standed Month Salary | Q2: Current Month Salary | R2: Basic | S2: HRA | T2: LTA | U2: Special Allowances | V2: Gross Salary | W2: One time Bonus | X2: Gratuity | Y2: Final Gross | Z2: Gross for PF | AA2: EPF Wages | AB2: P.F.(12%) | AC2: VPF | AD2: ESI (0.75%) | AE2: E.P.F. (8.33%) | AF2: P.F. (3.67%) | AG2: ESI (3.25%) | AH2: TDS | AI2: Any Others / Advance | AJ2: Insurance Advance | AK2: Profession Tax | AL2: LWF | AM2: (PF+ESI+LWF) | AN2: Net Salary | AO2: Commnets | AP2: No. of completed year of service (Gratuity) | AQ2: Last drwan Basic Salary | AR2: Gratutiy Amount
A3: 1 | B3: JAI-042 | C3: 43983 | E3: Anchor | F3: 50100302993158 | G3: HDFC0001635 | H3: 101548467393 | I3: FENPM4917N | J3: 5216260893 | K3: 35560 | L3: Female | M3: Semi-skilled | N3: =VLOOKUP(B3,'Anchor-Attendance'!$B$4:$K$84,10,0) -> 46072 | O3: =VLOOKUP(B3,'Anchor-Attendance'!$B$4:$BB$84,53,0) -> 19 | P3: 12360 | Q3: =P3/$O$1*O3 -> 8387.1429 | R3: =Q3*100% -> 8387.1429 | S3: 0 | T3: 0 | U3: 0 | V3: =ROUND(SUM(R3:U3),0) -> 8387 | W3: =12360-V3 -> 3973 | X3: =AR3 -> 42785 | Y3: =SUM(V3:X3) -> 55145 | Z3: =ROUND(SUM(R3:U3)-S3,0) -> 8387 | AA3: =ROUND(IF(Z3>15000,15000,Z3),0) -> 8387 | AB3: =ROUND(IF(Z3>15000,1800,Z3*12%),0) -> 1006 | AC3: 0 | AD3: =ROUNDUP(IF(P3>21000,0,(Y3-X3)*0.75%),0) -> 93 | AE3: =ROUND(AB3/12%*8.33%,0) -> 698 | AF3: =+AB3-AE3 -> 308 | AG3: =IF(P3>21000,0,(Y3-X3)*3.25%) -> 401.7 | AH3: 0 | AI3: 0 | AJ3: 0 | AK3: =IF((Y3-X3)>=20001,200,IF((Y3-X3)>=15001,150,0)) -> 0 | AL3: 0 | AM3: =AB3+AD3+AL3 -> 1099 | AN3: =SUM(ROUND((Y3)-(AH3+AI3+AJ3+AK3+AM3),0),0) -> 54046 | AO3: Full month salary to be paid | AP3: =ROUND((N3-C3)/365,0) -> 6 | AQ3: =P3 -> 12360 | AR3: =ROUND(AQ3*15/26*AP3,0) -> 42785
A4: =A3+1 -> 2 | B4: JAI-060 | C4: 43983 | E4: Anchor | F4: 50100326226811 | G4: HDFC0001635 | H4: 101548467653 | I4: BPTPN8806A | J4: 5216240667 | K4: 34141 | L4: Female | M4: Semi-skilled | N4: =VLOOKUP(B4,'Anchor-Attendance'!$B$4:$K$84,10,0) -> 46072 | O4: =VLOOKUP(B4,'Anchor-Attendance'!$B$4:$BB$84,53,0) -> 19 | P4: 12360 | Q4: =P4/$O$1*O4 -> 8387.1429 | R4: =Q4*100% -> 8387.1429 | S4: 0 | T4: 0 | U4: 0 | V4: =ROUND(SUM(R4:U4),0) -> 8387 | W4: =12360-V4 -> 3973 | X4: =AR4 -> 42785 | Y4: =SUM(V4:X4) -> 55145 | Z4: =ROUND(SUM(R4:U4)-S4,0) -> 8387 | AA4: =ROUND(IF(Z4>15000,15000,Z4),0) -> 8387 | AB4: =ROUND(IF(Z4>15000,1800,Z4*12%),0) -> 1006 | AC4: 0 | AD4: =ROUNDUP(IF(P4>21000,0,(Y4-X4)*0.75%),0) -> 93 | AE4: =ROUND(AB4/12%*8.33%,0) -> 698 | AF4: =+AB4-AE4 -> 308 | AG4: =IF(P4>21000,0,(Y4-X4)*3.25%) -> 401.7 | AH4: 0 | AI4: 0 | AJ4: 0 | AK4: =IF((Y4-X4)>=20001,200,IF((Y4-X4)>=15001,150,0)) -> 0 | AL4: 0 | AM4: =AB4+AD4+AL4 -> 1099 | AN4: =SUM(ROUND((Y4)-(AH4+AI4+AJ4+AK4+AM4),0),0) -> 54046 | AO4: Full month salary to be paid | AP4: =ROUND((N4-C4)/365,0) -> 6 | AQ4: =P4 -> 12360 | AR4: =ROUND(AQ4*15/26*AP4,0) -> 42785
A5: =A4+1 -> 3 | B5: JAI-081 | C5: 43983 | E5: Anchor | F5: 50100302993145 | G5: HDFC0001635 | H5: 101589851810 | I5: JNFPK9704N | J5: 5216601062 | K5: 35958 | L5: Female | M5: Semi-skilled | N5: No | O5: =VLOOKUP(B5,'Anchor-Attendance'!$B$4:$BB$84,53,0) -> 28 | P5: 12360 | Q5: =P5/$O$1*O5 -> 12360 | R5: =Q5*100% -> 12360 | S5: 0 | T5: 0 | U5: 0 | V5: =ROUND(SUM(R5:U5),0) -> 12360 | W5: 0 | X5: 0 | Y5: =SUM(V5:X5) -> 12360 | Z5: =ROUND(SUM(R5:U5)-S5,0) -> 12360 | AA5: =ROUND(IF(Z5>15000,15000,Z5),0) -> 12360 | AB5: =ROUND(IF(Z5>15000,1800,Z5*12%),0) -> 1483 | AC5: 0 | AD5: =ROUNDUP(IF(P5>21000,0,(Y5-X5)*0.75%),0) -> 93 | AE5: =ROUND(AB5/12%*8.33%,0) -> 1029 | AF5: =+AB5-AE5 -> 454 | AG5: =IF(P5>21000,0,(Y5-X5)*3.25%) -> 401.7 | AH5: 0 | AI5: 0 | AJ5: 0 | AK5: =IF((Y5-X5)>=20001,200,IF((Y5-X5)>=15001,150,0)) -> 0 | AL5: 0 | AM5: =AB5+AD5+AL5 -> 1576 | AN5: =SUM(ROUND((Y5)-(AH5+AI5+AJ5+AK5+AM5),0),0) -> 10784
A6: =A5+1 -> 4 | B6: JAI-098 | C6: 43983 | E6: Anchor | F6: 50100302993694 | G6: HDFC0001635 | H6: 101548467892 | I6: FNTPP6732H | J6: 5216242698 | K6: 35266 | L6: Female | M6: Semi-skilled | N6: No | O6: =VLOOKUP(B6,'Anchor-Attendance'!$B$4:$BB$84,53,0) -> 28 | P6: 12360 | Q6: =P6/$O$1*O6 -> 12360 | R6: =Q6*100% -> 12360 | S6: 0 | T6: 0 | U6: 0 | V6: =ROUND(SUM(R6:U6),0) -> 12360 | W6: 0 | X6: 0 | Y6: =SUM(V6:X6) -> 12360 | Z6: =ROUND(SUM(R6:U6)-S6,0) -> 12360 | AA6: =ROUND(IF(Z6>15000,15000,Z6),0) -> 12360 | AB6: =ROUND(IF(Z6>15000,1800,Z6*12%),0) -> 1483 | AC6: 0 | AD6: =ROUNDUP(IF(P6>21000,0,(Y6-X6)*0.75%),0) -> 93 | AE6: =ROUND(AB6/12%*8.33%,0) -> 1029 | AF6: =+AB6-AE6 -> 454 | AG6: =IF(P6>21000,0,(Y6-X6)*3.25%) -> 401.7 | AH6: 0 | AI6: 0 | AJ6: 0 | AK6: =IF((Y6-X6)>=20001,200,IF((Y6-X6)>=15001,150,0)) -> 0 | AL6: 0 | AM6: =AB6+AD6+AL6 -> 1576 | AN6: =SUM(ROUND((Y6)-(AH6+AI6+AJ6+AK6+AM6),0),0) -> 10784
A7: =A6+1 -> 5 | B7: JAI-144 | C7: 44075 | E7: Anchor | F7: 50100373849809 | G7: HDFC0001635 | H7: 101620639348 | I7: DJDPM2220M | J7: 5216743492 | K7: 35292 | L7: Female | M7: Semi-skilled | N7: No | O7: =VLOOKUP(B7,'Anchor-Attendance'!$B$4:$BB$84,53,0) -> 28 | P7: 12360 | Q7: =P7/$O$1*O7 -> 12360 | R7: =Q7*100% -> 12360 | S7: 0 | T7: 0 | U7: 0 | V7: =ROUND(SUM(R7:U7),0) -> 12360 | W7: 0 | X7: 0 | Y7: =SUM(V7:X7) -> 12360 | Z7: =ROUND(SUM(R7:U7)-S7,0) -> 12360 | AA7: =ROUND(IF(Z7>15000,15000,Z7),0) -> 12360 | AB7: =ROUND(IF(Z7>15000,1800,Z7*12%),0) -> 1483 | AC7: 0 | AD7: =ROUNDUP(IF(P7>21000,0,(Y7-X7)*0.75%),0) -> 93 | AE7: =ROUND(AB7/12%*8.33%,0) -> 1029 | AF7: =+AB7-AE7 -> 454 | AG7: =IF(P7>21000,0,(Y7-X7)*3.25%) -> 401.7 | AH7: 0 | AI7: 0 | AJ7: 0 | AK7: =IF((Y7-X7)>=20001,200,IF((Y7-X7)>=15001,150,0)) -> 0 | AL7: 0 | AM7: =AB7+AD7+AL7 -> 1576 | AN7: =SUM(ROUND((Y7)-(AH7+AI7+AJ7+AK7+AM7),0),0) -> 10784
A8: =A7+1 -> 6 | B8: JAI-148 | C8: 44075 | E8: Anchor | F8: 50100373849555 | G8: HDFC0001635 | H8: 101641624231 | I8: IFSPP2656L | J8: 5216745322 | K8: 36741 | L8: Female | M8: Semi-skilled | N8: No | O8: =VLOOKUP(B8,'Anchor-Attendance'!$B$4:$BB$84,53,0) -> 28 | P8: 12360 | Q8: =P8/$O$1*O8 -> 12360 | R8: =Q8*100% -> 12360 | S8: 0 | T8: 0 | U8: 0 | V8: =ROUND(SUM(R8:U8),0) -> 12360 | W8: 0 | X8: 0 | Y8: =SUM(V8:X8) -> 12360 | Z8: =ROUND(SUM(R8:U8)-S8,0) -> 12360 | AA8: =ROUND(IF(Z8>15000,15000,Z8),0) -> 12360 | AB8: =ROUND(IF(Z8>15000,1800,Z8*12%),0) -> 1483 | AC8: 0 | AD8: =ROUNDUP(IF(P8>21000,0,(Y8-X8)*0.75%),0) -> 93 | AE8: =ROUND(AB8/12%*8.33%,0) -> 1029 | AF8: =+AB8-AE8 -> 454 | AG8: =IF(P8>21000,0,(Y8-X8)*3.25%) -> 401.7 | AH8: 0 | AI8: 0 | AJ8: 0 | AK8: =IF((Y8-X8)>=20001,200,IF((Y8-X8)>=15001,150,0)) -> 0 | AL8: 0 | AM8: =AB8+AD8+AL8 -> 1576 | AN8: =SUM(ROUND((Y8)-(AH8+AI8+AJ8+AK8+AM8),0),0) -> 10784
A9: =A8+1 -> 7 | B9: JAI-173 | C9: 44131 | E9: Anchor | F9: 50100389932244 | G9: HDFC0000240 | H9: 101641624220 | I9: COLPJ2745G | J9: 5216892953 | K9: 35455 | L9: Female | M9: Semi-skilled | N9: No | O9: =VLOOKUP(B9,'Anchor-Attendance'!$B$4:$BB$84,53,0) -> 28 | P9: 12360 | Q9: =P9/$O$1*O9 -> 12360 | R9: =Q9*100% -> 12360 | S9: 0 | T9: 0 | U9: 0 | V9: =ROUND(SUM(R9:U9),0) -> 12360 | W9: 0 | X9: 0 | Y9: =SUM(V9:X9) -> 12360 | Z9: =ROUND(SUM(R9:U9)-S9,0) -> 12360 | AA9: =ROUND(IF(Z9>15000,15000,Z9),0) -> 12360 | AB9: =ROUND(IF(Z9>15000,1800,Z9*12%),0) -> 1483 | AC9: 0 | AD9: =ROUNDUP(IF(P9>21000,0,(Y9-X9)*0.75%),0) -> 93 | AE9: =ROUND(AB9/12%*8.33%,0) -> 1029 | AF9: =+AB9-AE9 -> 454 | AG9: =IF(P9>21000,0,(Y9-X9)*3.25%) -> 401.7 | AH9: 0 | AI9: 0 | AJ9: 0 | AK9: =IF((Y9-X9)>=20001,200,IF((Y9-X9)>=15001,150,0)) -> 0 | AL9: 0 | AM9: =AB9+AD9+AL9 -> 1576 | AN9: =SUM(ROUND((Y9)-(AH9+AI9+AJ9+AK9+AM9),0),0) -> 10784
A10: =A9+1 -> 8 | B10: JAI-246 | C10: 44326 | E10: Anchor | F10: 50100426485354 | G10: HDFC0000240 | H10: 101693034754 | I10: DUCPA7598L | J10: 5217396231 | K10: 36160 | L10: Female | M10: Semi-skilled | N10: No | O10: =VLOOKUP(B10,'Anchor-Attendance'!$B$4:$BB$84,53,0) -> 28 | P10: 12360 | Q10: =P10/$O$1*O10 -> 12360 | R10: =Q10*100% -> 12360 | S10: 0 | T10: 0 | U10: 0 | V10: =ROUND(SUM(R10:U10),0) -> 12360 | W10: 0 | X10: 0 | Y10: =SUM(V10:X10) -> 12360 | Z10: =ROUND(SUM(R10:U10)-S10,0) -> 12360 | AA10: =ROUND(IF(Z10>15000,15000,Z10),0) -> 12360 | AB10: =ROUND(IF(Z10>15000,1800,Z10*12%),0) -> 1483 | AC10: 0 | AD10: =ROUNDUP(IF(P10>21000,0,(Y10-X10)*0.75%),0) -> 93 | AE10: =ROUND(AB10/12%*8.33%,0) -> 1029 | AF10: =+AB10-AE10 -> 454 | AG10: =IF(P10>21000,0,(Y10-X10)*3.25%) -> 401.7 | AH10: 0 | AI10: 0 | AJ10: 0 | AK10: =IF((Y10-X10)>=20001,200,IF((Y10-X10)>=15001,150,0)) -> 0 | AL10: 0 | AM10: =AB10+AD10+AL10 -> 1576 | AN10: =SUM(ROUND((Y10)-(AH10+AI10+AJ10+AK10+AM10),0),0) -> 10784
A11: =A10+1 -> 9 | B11: JAI-248 | C11: 44326 | E11: Anchor | F11: 50100421884544 | G11: HDFC0000240 | H11: 101693033653 | I11: FPPPB7330B | J11: 5217395947 | K11: 33201 | L11: Female | M11: Semi-skilled | N11: No | O11: =VLOOKUP(B11,'Anchor-Attendance'!$B$4:$BB$84,53,0) -> 28 | P11: 12360 | Q11: =P11/$O$1*O11 -> 12360 | R11: =Q11*100% -> 12360 | S11: 0 | T11: 0 | U11: 0 | V11: =ROUND(SUM(R11:U11),0) -> 12360 | W11: 0 | X11: 0 | Y11: =SUM(V11:X11) -> 12360 | Z11: =ROUND(SUM(R11:U11)-S11,0) -> 12360 | AA11: =ROUND(IF(Z11>15000,15000,Z11),0) -> 12360 | AB11: =ROUND(IF(Z11>15000,1800,Z11*12%),0) -> 1483 | AC11: 0 | AD11: =ROUNDUP(IF(P11>21000,0,(Y11-X11)*0.75%),0) -> 93 | AE11: =ROUND(AB11/12%*8.33%,0) -> 1029 | AF11: =+AB11-AE11 -> 454 | AG11: =IF(P11>21000,0,(Y11-X11)*3.25%) -> 401.7 | AH11: 0 | AI11: 0 | AJ11: 0 | AK11: =IF((Y11-X11)>=20001,200,IF((Y11-X11)>=15001,150,0)) -> 0 | AL11: 0 | AM11: =AB11+AD11+AL11 -> 1576 | AN11: =SUM(ROUND((Y11)-(AH11+AI11+AJ11+AK11+AM11),0),0) -> 10784
A12: =A11+1 -> 10 | B12: JAI-260 | C12: 44326 | E12: Anchor | F12: 50100426485519 | G12: HDFC0000240 | H12: 101693033109 | I12: FFGPR2158Q | J12: 5217398845 | K12: 35586 | L12: Female | M12: Semi-skilled | N12: No | O12: =VLOOKUP(B12,'Anchor-Attendance'!$B$4:$BB$84,53,0) -> 12 | P12: 12360 | Q12: =P12/$O$1*O12 -> 5297.1429 | R12: =Q12*100% -> 5297.1429 | S12: 0 | T12: 0 | U12: 0 | V12: =ROUND(SUM(R12:U12),0) -> 5297 | W12: 0 | X12: 0 | Y12: =SUM(V12:X12) -> 5297 | Z12: =ROUND(SUM(R12:U12)-S12,0) -> 5297 | AA12: =ROUND(IF(Z12>15000,15000,Z12),0) -> 5297 | AB12: =ROUND(IF(Z12>15000,1800,Z12*12%),0) -> 636 | AC12: 0 | AD12: =ROUNDUP(IF(P12>21000,0,(Y12-X12)*0.75%),0) -> 40 | AE12: =ROUND(AB12/12%*8.33%,0) -> 441 | AF12: =+AB12-AE12 -> 195 | AG12: =IF(P12>21000,0,(Y12-X12)*3.25%) -> 172.1525 | AH12: 0 | AI12: 0 | AJ12: 0 | AK12: =IF((Y12-X12)>=20001,200,IF((Y12-X12)>=15001,150,0)) -> 0 | AL12: 0 | AM12: =AB12+AD12+AL12 -> 676 | AN12: =SUM(ROUND((Y12)-(AH12+AI12+AJ12+AK12+AM12),0),0) -> 4621
A13: =A12+1 -> 11 | B13: JAI-264 | C13: 44326 | E13: Anchor | F13: 50100419974035 | G13: HDFC0001635 | H13: 101693033121 | I13: OEQPS9295D | J13: 5217404380 | K13: 36137 | L13: Female | M13: Semi-skilled | N13: No | O13: =VLOOKUP(B13,'Anchor-Attendance'!$B$4:$BB$84,53,0) -> 0 | P13: 12360 | Q13: =P13/$O$1*O13 -> 0 | R13: =Q13*100% -> 0 | S13: 0 | T13: 0 | U13: 0 | V13: =ROUND(SUM(R13:U13),0) -> 0 | W13: 0 | X13: 0 | Y13: =SUM(V13:X13) -> 0 | Z13: =ROUND(SUM(R13:U13)-S13,0) -> 0 | AA13: =ROUND(IF(Z13>15000,15000,Z13),0) -> 0 | AB13: =ROUND(IF(Z13>15000,1800,Z13*12%),0) -> 0 | AC13: 0 | AD13: =ROUNDUP(IF(P13>21000,0,(Y13-X13)*0.75%),0) -> 0 | AE13: =ROUND(AB13/12%*8.33%,0) -> 0 | AF13: =+AB13-AE13 -> 0 | AG13: =IF(P13>21000,0,(Y13-X13)*3.25%) -> 0 | AH13: 0 | AI13: 0 | AJ13: 0 | AK13: =IF((Y13-X13)>=20001,200,IF((Y13-X13)>=15001,150,0)) -> 0 | AL13: 0 | AM13: =AB13+AD13+AL13 -> 0 | AN13: =SUM(ROUND((Y13)-(AH13+AI13+AJ13+AK13+AM13),0),0) -> 0
A14: =A13+1 -> 12 | B14: JAI-265 | C14: 44326 | E14: Anchor | F14: 50100419974686 | G14: HDFC0001635 | H14: 101693033676 | I14: OENPS6494M | J14: 5217396008 | K14: 37108 | L14: Female | M14: Semi-skilled | N14: No | O14: =VLOOKUP(B14,'Anchor-Attendance'!$B$4:$BB$84,53,0) -> 28 | P14: 12360 | Q14: =P14/$O$1*O14 -> 12360 | R14: =Q14*100% -> 12360 | S14: 0 | T14: 0 | U14: 0 | V14: =ROUND(SUM(R14:U14),0) -> 12360 | W14: 0 | X14: 0 | Y14: =SUM(V14:X14) -> 12360 | Z14: =ROUND(SUM(R14:U14)-S14,0) -> 12360 | AA14: =ROUND(IF(Z14>15000,15000,Z14),0) -> 12360 | AB14: =ROUND(IF(Z14>15000,1800,Z14*12%),0) -> 1483 | AC14: 0 | AD14: =ROUNDUP(IF(P14>21000,0,(Y14-X14)*0.75%),0) -> 93 | AE14: =ROUND(AB14/12%*8.33%,0) -> 1029 | AF14: =+AB14-AE14 -> 454 | AG14: =IF(P14>21000,0,(Y14-X14)*3.25%) -> 401.7 | AH14: 0 | AI14: 0 | AJ14: 0 | AK14: =IF((Y14-X14)>=20001,200,IF((Y14-X14)>=15001,150,0)) -> 0 | AL14: 0 | AM14: =AB14+AD14+AL14 -> 1576 | AN14: =SUM(ROUND((Y14)-(AH14+AI14+AJ14+AK14+AM14),0),0) -> 10784
A15: =A14+1 -> 13 | B15: JAI-268 | C15: 44326 | E15: Anchor | F15: 50100426462022 | G15: HDFC0000240 | H15: 101693034708 | I15: ODGPS5639G | J15: 5217395028 | K15: 34097 | L15: Female | M15: Semi-skilled | N15: No | O15: =VLOOKUP(B15,'Anchor-Attendance'!$B$4:$BB$84,53,0) -> 28 | P15: 12360 | Q15: =P15/$O$1*O15 -> 12360 | R15: =Q15*100% -> 12360 | S15: 0 | T15: 0 | U15: 0 | V15: =ROUND(SUM(R15:U15),0) -> 12360 | W15: 0 | X15: 0 | Y15: =SUM(V15:X15) -> 12360 | Z15: =ROUND(SUM(R15:U15)-S15,0) -> 12360 | AA15: =ROUND(IF(Z15>15000,15000,Z15),0) -> 12360 | AB15: =ROUND(IF(Z15>15000,1800,Z15*12%),0) -> 1483 | AC15: 0 | AD15: =ROUNDUP(IF(P15>21000,0,(Y15-X15)*0.75%),0) -> 93 | AE15: =ROUND(AB15/12%*8.33%,0) -> 1029 | AF15: =+AB15-AE15 -> 454 | AG15: =IF(P15>21000,0,(Y15-X15)*3.25%) -> 401.7 | AH15: 0 | AI15: 0 | AJ15: 0 | AK15: =IF((Y15-X15)>=20001,200,IF((Y15-X15)>=15001,150,0)) -> 0 | AL15: 0 | AM15: =AB15+AD15+AL15 -> 1576 | AN15: =SUM(ROUND((Y15)-(AH15+AI15+AJ15+AK15+AM15),0),0) -> 10784
A16: =A15+1 -> 14 | B16: JAI-270 | C16: 44326 | E16: Anchor | F16: 50100419974009 | G16: HDFC0001635 | H16: 101693033703 | I16: NFXPS9700G | J16: 5217396164 | K16: 36748 | L16: Female | M16: Semi-skilled | N16: No | O16: =VLOOKUP(B16,'Anchor-Attendance'!$B$4:$BB$84,53,0) -> 28 | P16: 12360 | Q16: =P16/$O$1*O16 -> 12360 | R16: =Q16*100% -> 12360 | S16: 0 | T16: 0 | U16: 0 | V16: =ROUND(SUM(R16:U16),0) -> 12360 | W16: 0 | X16: 0 | Y16: =SUM(V16:X16) -> 12360 | Z16: =ROUND(SUM(R16:U16)-S16,0) -> 12360 | AA16: =ROUND(IF(Z16>15000,15000,Z16),0) -> 12360 | AB16: =ROUND(IF(Z16>15000,1800,Z16*12%),0) -> 1483 | AC16: 0 | AD16: =ROUNDUP(IF(P16>21000,0,(Y16-X16)*0.75%),0) -> 93 | AE16: =ROUND(AB16/12%*8.33%,0) -> 1029 | AF16: =+AB16-AE16 -> 454 | AG16: =IF(P16>21000,0,(Y16-X16)*3.25%) -> 401.7 | AH16: 0 | AI16: 0 | AJ16: 0 | AK16: =IF((Y16-X16)>=20001,200,IF((Y16-X16)>=15001,150,0)) -> 0 | AL16: 0 | AM16: =AB16+AD16+AL16 -> 1576 | AN16: =SUM(ROUND((Y16)-(AH16+AI16+AJ16+AK16+AM16),0),0) -> 10784
A17: =A16+1 -> 15 | B17: JAI-275 | C17: 44342 | E17: Anchor | F17: 50100422491859 | G17: HDFC0000472 | H17: 101693033761 | I17: FCWPD2945A | J17: 5217417695 | K17: 34570 | L17: Female | M17: Semi-skilled | N17: =VLOOKUP(B17,'Anchor-Attendance'!$B$4:$K$84,10,0) -> 46059 | O17: =VLOOKUP(B17,'Anchor-Attendance'!$B$4:$BB$84,53,0) -> 5 | P17: 12360 | Q17: =P17/$O$1*O17 -> 2207.1429 | R17: =Q17*100% -> 2207.1429 | S17: 0 | T17: 0 | U17: 0 | V17: =ROUND(SUM(R17:U17),0) -> 2207 | W17: 0 | X17: =AR17 -> 35654 | Y17: =SUM(V17:X17) -> 37861 | Z17: =ROUND(SUM(R17:U17)-S17,0) -> 2207 | AA17: =ROUND(IF(Z17>15000,15000,Z17),0) -> 2207 | AB17: =ROUND(IF(Z17>15000,1800,Z17*12%),0) -> 265 | AC17: 0 | AD17: =ROUNDUP(IF(P17>21000,0,(Y17-X17)*0.75%),0) -> 17 | AE17: =ROUND(AB17/12%*8.33%,0) -> 184 | AF17: =+AB17-AE17 -> 81 | AG17: =IF(P17>21000,0,(Y17-X17)*3.25%) -> 71.7275 | AH17: 0 | AI17: 0 | AJ17: 0 | AK17: =IF((Y17-X17)>=20001,200,IF((Y17-X17)>=15001,150,0)) -> 0 | AL17: 0 | AM17: =AB17+AD17+AL17 -> 282 | AN17: =SUM(ROUND((Y17)-(AH17+AI17+AJ17+AK17+AM17),0),0) -> 37579 | AP17: =ROUND((N17-C17)/365,0) -> 5 | AQ17: =P17 -> 12360 | AR17: =ROUND(AQ17*15/26*AP17,0) -> 35654
A18: =A17+1 -> 16 | B18: JAI-277 | C18: 44342 | E18: Anchor | F18: 50100428958172 | G18: HDFC0002352 | H18: 101693032161 | I18: AFFPE6498C | J18: 5217418388 | K18: 36126 | L18: Female | M18: Semi-skilled | N18: =VLOOKUP(B18,'Anchor-Attendance'!$B$4:$K$84,10,0) -> 46072 | O18: =VLOOKUP(B18,'Anchor-Attendance'!$B$4:$BB$84,53,0) -> 19 | P18: 12360 | Q18: =P18/$O$1*O18 -> 8387.1429 | R18: =Q18*100% -> 8387.1429 | S18: 0 | T18: 0 | U18: 0 | V18: =ROUND(SUM(R18:U18),0) -> 8387 | W18: =12360-V18 -> 3973 | X18: =AR18 -> 35654 | Y18: =SUM(V18:X18) -> 48014 | Z18: =ROUND(SUM(R18:U18)-S18,0) -> 8387 | AA18: =ROUND(IF(Z18>15000,15000,Z18),0) -> 8387 | AB18: =ROUND(IF(Z18>15000,1800,Z18*12%),0) -> 1006 | AC18: 0 | AD18: =ROUNDUP(IF(P18>21000,0,(Y18-X18)*0.75%),0) -> 93 | AE18: =ROUND(AB18/12%*8.33%,0) -> 698 | AF18: =+AB18-AE18 -> 308 | AG18: =IF(P18>21000,0,(Y18-X18)*3.25%) -> 401.7 | AH18: 0 | AI18: 0 | AJ18: 0 | AK18: =IF((Y18-X18)>=20001,200,IF((Y18-X18)>=15001,150,0)) -> 0 | AL18: 0 | AM18: =AB18+AD18+AL18 -> 1099 | AN18: =SUM(ROUND((Y18)-(AH18+AI18+AJ18+AK18+AM18),0),0) -> 46915 | AO18: Full month salary to be paid | AP18: =ROUND((N18-C18)/365,0) -> 5 | AQ18: =P18 -> 12360 | AR18: =ROUND(AQ18*15/26*AP18,0) -> 35654
A19: =A18+1 -> 17 | B19: JAI-301 | C19: 44426 | E19: Anchor | F19: 50100453957155 | G19: HDFC0001635 | H19: 101722628512 | I19: EFXPA7539L | J19: 5217668558 | K19: 36765 | L19: Female | M19: Semi-skilled | N19: No | O19: =VLOOKUP(B19,'Anchor-Attendance'!$B$4:$BB$84,53,0) -> 26 | P19: 12360 | Q19: =P19/$O$1*O19 -> 11477.143 | R19: =Q19*100% -> 11477.143 | S19: 0 | T19: 0 | U19: 0 | V19: =ROUND(SUM(R19:U19),0) -> 11477 | W19: 0 | X19: 0 | Y19: =SUM(V19:X19) -> 11477 | Z19: =ROUND(SUM(R19:U19)-S19,0) -> 11477 | AA19: =ROUND(IF(Z19>15000,15000,Z19),0) -> 11477 | AB19: =ROUND(IF(Z19>15000,1800,Z19*12%),0) -> 1377 | AC19: 0 | AD19: =ROUNDUP(IF(P19>21000,0,(Y19-X19)*0.75%),0) -> 87 | AE19: =ROUND(AB19/12%*8.33%,0) -> 956 | AF19: =+AB19-AE19 -> 421 | AG19: =IF(P19>21000,0,(Y19-X19)*3.25%) -> 373.0025 | AH19: 0 | AI19: 0 | AJ19: 0 | AK19: =IF((Y19-X19)>=20001,200,IF((Y19-X19)>=15001,150,0)) -> 0 | AL19: 0 | AM19: =AB19+AD19+AL19 -> 1464 | AN19: =SUM(ROUND((Y19)-(AH19+AI19+AJ19+AK19+AM19),0),0) -> 10013
A20: =A19+1 -> 18 | B20: JAI-310 | C20: 44426 | E20: Anchor | F20: 50100452150045 | G20: HDFC0003916 | H20: 101727707088 | I20: DKAPR8305G | J20: 5217663143 | K20: 34561 | L20: Female | M20: Semi-skilled | N20: No | O20: =VLOOKUP(B20,'Anchor-Attendance'!$B$4:$BB$84,53,0) -> 28 | P20: 12360 | Q20: =P20/$O$1*O20 -> 12360 | R20: =Q20*100% -> 12360 | S20: 0 | T20: 0 | U20: 0 | V20: =ROUND(SUM(R20:U20),0) -> 12360 | W20: 0 | X20: 0 | Y20: =SUM(V20:X20) -> 12360 | Z20: =ROUND(SUM(R20:U20)-S20,0) -> 12360 | AA20: =ROUND(IF(Z20>15000,15000,Z20),0) -> 12360 | AB20: =ROUND(IF(Z20>15000,1800,Z20*12%),0) -> 1483 | AC20: 0 | AD20: =ROUNDUP(IF(P20>21000,0,(Y20-X20)*0.75%),0) -> 93 | AE20: =ROUND(AB20/12%*8.33%,0) -> 1029 | AF20: =+AB20-AE20 -> 454 | AG20: =IF(P20>21000,0,(Y20-X20)*3.25%) -> 401.7 | AH20: 0 | AI20: 0 | AJ20: 0 | AK20: =IF((Y20-X20)>=20001,200,IF((Y20-X20)>=15001,150,0)) -> 0 | AL20: 0 | AM20: =AB20+AD20+AL20 -> 1576 | AN20: =SUM(ROUND((Y20)-(AH20+AI20+AJ20+AK20+AM20),0),0) -> 10784
A21: =A20+1 -> 19 | B21: JAI-314 | C21: 44426 | E21: Anchor | F21: 50100453956929 | G21: HDFC0001635 | H21: 101727707116 | I21: KZOPK0189K | J21: 5217664617 | K21: 36387 | L21: Female | M21: Semi-skilled | N21: No | O21: =VLOOKUP(B21,'Anchor-Attendance'!$B$4:$BB$84,53,0) -> 28 | P21: 12360 | Q21: =P21/$O$1*O21 -> 12360 | R21: =Q21*100% -> 12360 | S21: 0 | T21: 0 | U21: 0 | V21: =ROUND(SUM(R21:U21),0) -> 12360 | W21: 0 | X21: 0 | Y21: =SUM(V21:X21) -> 12360 | Z21: =ROUND(SUM(R21:U21)-S21,0) -> 12360 | AA21: =ROUND(IF(Z21>15000,15000,Z21),0) -> 12360 | AB21: =ROUND(IF(Z21>15000,1800,Z21*12%),0) -> 1483 | AC21: 0 | AD21: =ROUNDUP(IF(P21>21000,0,(Y21-X21)*0.75%),0) -> 93 | AE21: =ROUND(AB21/12%*8.33%,0) -> 1029 | AF21: =+AB21-AE21 -> 454 | AG21: =IF(P21>21000,0,(Y21-X21)*3.25%) -> 401.7 | AH21: 0 | AI21: 0 | AJ21: 0 | AK21: =IF((Y21-X21)>=20001,200,IF((Y21-X21)>=15001,150,0)) -> 0 | AL21: 0 | AM21: =AB21+AD21+AL21 -> 1576 | AN21: =SUM(ROUND((Y21)-(AH21+AI21+AJ21+AK21+AM21),0),0) -> 10784
A22: =A21+1 -> 20 | B22: JAI-321 | C22: 44426 | E22: Anchor | F22: 50100446212114 | G22: HDFC0001635 | H22: 101727707144 | I22: IUUPK5573G | J22: 5217664816 | K22: 35595 | L22: Female | M22: Semi-skilled | N22: =VLOOKUP(B22,'Anchor-Attendance'!$B$4:$K$84,10,0) -> 46059 | O22: =VLOOKUP(B22,'Anchor-Attendance'!$B$4:$BB$84,53,0) -> 6 | P22: 12360 | Q22: =P22/$O$1*O22 -> 2648.5714 | R22: =Q22*100% -> 2648.5714 | S22: 0 | T22: 0 | U22: 0 | V22: =ROUND(SUM(R22:U22),0) -> 2649 | W22: 0 | X22: =AR22 -> 0 | Y22: =SUM(V22:X22) -> 2649 | Z22: =ROUND(SUM(R22:U22)-S22,0) -> 2649 | AA22: =ROUND(IF(Z22>15000,15000,Z22),0) -> 2649 | AB22: =ROUND(IF(Z22>15000,1800,Z22*12%),0) -> 318 | AC22: 0 | AD22: =ROUNDUP(IF(P22>21000,0,(Y22-X22)*0.75%),0) -> 20 | AE22: =ROUND(AB22/12%*8.33%,0) -> 221 | AF22: =+AB22-AE22 -> 97 | AG22: =IF(P22>21000,0,(Y22-X22)*3.25%) -> 86.0925 | AH22: 0 | AI22: 0 | AJ22: 0 | AK22: =IF((Y22-X22)>=20001,200,IF((Y22-X22)>=15001,150,0)) -> 0 | AL22: 0 | AM22: =AB22+AD22+AL22 -> 338 | AN22: =SUM(ROUND((Y22)-(AH22+AI22+AJ22+AK22+AM22),0),0) -> 2311 | AP22: =ROUND((N22-C22)/365,0) -> 4
A23: =A22+1 -> 21 | B23: JAI-333 | C23: 44426 | E23: Anchor | F23: 50100453956892 | G23: HDFC0001635 | H23: 101728745071 | I23: NADPS4388P | J23: 5217668709 | K23: 35934 | L23: Female | M23: Semi-skilled | N23: No | O23: =VLOOKUP(B23,'Anchor-Attendance'!$B$4:$BB$84,53,0) -> 28 | P23: 12360 | Q23: =P23/$O$1*O23 -> 12360 | R23: =Q23*100% -> 12360 | S23: 0 | T23: 0 | U23: 0 | V23: =ROUND(SUM(R23:U23),0) -> 12360 | W23: 0 | X23: 0 | Y23: =SUM(V23:X23) -> 12360 | Z23: =ROUND(SUM(R23:U23)-S23,0) -> 12360 | AA23: =ROUND(IF(Z23>15000,15000,Z23),0) -> 12360 | AB23: =ROUND(IF(Z23>15000,1800,Z23*12%),0) -> 1483 | AC23: 0 | AD23: =ROUNDUP(IF(P23>21000,0,(Y23-X23)*0.75%),0) -> 93 | AE23: =ROUND(AB23/12%*8.33%,0) -> 1029 | AF23: =+AB23-AE23 -> 454 | AG23: =IF(P23>21000,0,(Y23-X23)*3.25%) -> 401.7 | AH23: 0 | AI23: 0 | AJ23: 0 | AK23: =IF((Y23-X23)>=20001,200,IF((Y23-X23)>=15001,150,0)) -> 0 | AL23: 0 | AM23: =AB23+AD23+AL23 -> 1576 | AN23: =SUM(ROUND((Y23)-(AH23+AI23+AJ23+AK23+AM23),0),0) -> 10784
A24: =A23+1 -> 22 | B24: JAI-338 | C24: 44431 | E24: Anchor | F24: 50100453956994 | G24: HDFC0001635 | H24: 101727707349 | I24: FWMPB6525E | J24: 5217671547 | K24: 38047 | L24: Female | M24: Semi-skilled | N24: =VLOOKUP(B24,'Anchor-Attendance'!$B$4:$K$84,10,0) -> 46073 | O24: =VLOOKUP(B24,'Anchor-Attendance'!$B$4:$BB$84,53,0) -> 20 | P24: 12360 | Q24: =P24/$O$1*O24 -> 8828.5714 | R24: =Q24*100% -> 8828.5714 | S24: 0 | T24: 0 | U24: 0 | V24: =ROUND(SUM(R24:U24),0) -> 8829 | W24: =12360-V24 -> 3531 | X24: =AR24 -> 0 | Y24: =SUM(V24:X24) -> 12360 | Z24: =ROUND(SUM(R24:U24)-S24,0) -> 8829 | AA24: =ROUND(IF(Z24>15000,15000,Z24),0) -> 8829 | AB24: =ROUND(IF(Z24>15000,1800,Z24*12%),0) -> 1059 | AC24: 0 | AD24: =ROUNDUP(IF(P24>21000,0,(Y24-X24)*0.75%),0) -> 93 | AE24: =ROUND(AB24/12%*8.33%,0) -> 735 | AF24: =+AB24-AE24 -> 324 | AG24: =IF(P24>21000,0,(Y24-X24)*3.25%) -> 401.7 | AH24: 0 | AI24: 0 | AJ24: 0 | AK24: =IF((Y24-X24)>=20001,200,IF((Y24-X24)>=15001,150,0)) -> 0 | AL24: 0 | AM24: =AB24+AD24+AL24 -> 1152 | AN24: =SUM(ROUND((Y24)-(AH24+AI24+AJ24+AK24+AM24),0),0) -> 11208 | AO24: Full month salary to be paid | AP24: =ROUND((N24-C24)/365,0) -> 4
A25: =A24+1 -> 23 | B25: JAI-342 | C25: 44431 | E25: Anchor | F25: 50100453957027 | G25: HDFC0003916 | H25: 101721443487 | I25: GKOPP8991P | J25: 5217671469 | K25: 34898 | L25: Female | M25: Semi-skilled | N25: No | O25: =VLOOKUP(B25,'Anchor-Attendance'!$B$4:$BB$84,53,0) -> 28 | P25: 12360 | Q25: =P25/$O$1*O25 -> 12360 | R25: =Q25*100% -> 12360 | S25: 0 | T25: 0 | U25: 0 | V25: =ROUND(SUM(R25:U25),0) -> 12360 | W25: 0 | X25: 0 | Y25: =SUM(V25:X25) -> 12360 | Z25: =ROUND(SUM(R25:U25)-S25,0) -> 12360 | AA25: =ROUND(IF(Z25>15000,15000,Z25),0) -> 12360 | AB25: =ROUND(IF(Z25>15000,1800,Z25*12%),0) -> 1483 | AC25: 0 | AD25: =ROUNDUP(IF(P25>21000,0,(Y25-X25)*0.75%),0) -> 93 | AE25: =ROUND(AB25/12%*8.33%,0) -> 1029 | AF25: =+AB25-AE25 -> 454 | AG25: =IF(P25>21000,0,(Y25-X25)*3.25%) -> 401.7 | AH25: 0 | AI25: 0 | AJ25: 0 | AK25: =IF((Y25-X25)>=20001,200,IF((Y25-X25)>=15001,150,0)) -> 0 | AL25: 0 | AM25: =AB25+AD25+AL25 -> 1576 | AN25: =SUM(ROUND((Y25)-(AH25+AI25+AJ25+AK25+AM25),0),0) -> 10784
A26: =A25+1 -> 24 | B26: JAI-377 | C26: 44522 | E26: Anchor | F26: 50100453958616 | G26: HDFC0001635 | H26: 101758025155 | I26: CPEPN3528R | J26: 5217964768 | K26: 36557 | L26: Female | M26: Semi-skilled | N26: No | O26: =VLOOKUP(B26,'Anchor-Attendance'!$B$4:$BB$84,53,0) -> 28 | P26: 12360 | Q26: =P26/$O$1*O26 -> 12360 | R26: =Q26*100% -> 12360 | S26: 0 | T26: 0 | U26: 0 | V26: =ROUND(SUM(R26:U26),0) -> 12360 | W26: 0 | X26: 0 | Y26: =SUM(V26:X26) -> 12360 | Z26: =ROUND(SUM(R26:U26)-S26,0) -> 12360 | AA26: =ROUND(IF(Z26>15000,15000,Z26),0) -> 12360 | AB26: =ROUND(IF(Z26>15000,1800,Z26*12%),0) -> 1483 | AC26: 0 | AD26: =ROUNDUP(IF(P26>21000,0,(Y26-X26)*0.75%),0) -> 93 | AE26: =ROUND(AB26/12%*8.33%,0) -> 1029 | AF26: =+AB26-AE26 -> 454 | AG26: =IF(P26>21000,0,(Y26-X26)*3.25%) -> 401.7 | AH26: 0 | AI26: 0 | AJ26: 0 | AK26: =IF((Y26-X26)>=20001,200,IF((Y26-X26)>=15001,150,0)) -> 0 | AL26: 0 | AM26: =AB26+AD26+AL26 -> 1576 | AN26: =SUM(ROUND((Y26)-(AH26+AI26+AJ26+AK26+AM26),0),0) -> 10784
A27: =A26+1 -> 25 | B27: JAI-382 | C27: 44522 | E27: Anchor | F27: 50100453957461 | G27: HDFC0001635 | H27: 101758030367 | I27: FMRPR4408H | J27: 5217967622 | K27: 36525 | L27: Female | M27: Semi-skilled | N27: No | O27: =VLOOKUP(B27,'Anchor-Attendance'!$B$4:$BB$84,53,0) -> 28 | P27: 12360 | Q27: =P27/$O$1*O27 -> 12360 | R27: =Q27*100% -> 12360 | S27: 0 | T27: 0 | U27: 0 | V27: =ROUND(SUM(R27:U27),0) -> 12360 | W27: 0 | X27: 0 | Y27: =SUM(V27:X27) -> 12360 | Z27: =ROUND(SUM(R27:U27)-S27,0) -> 12360 | AA27: =ROUND(IF(Z27>15000,15000,Z27),0) -> 12360 | AB27: =ROUND(IF(Z27>15000,1800,Z27*12%),0) -> 1483 | AC27: 0 | AD27: =ROUNDUP(IF(P27>21000,0,(Y27-X27)*0.75%),0) -> 93 | AE27: =ROUND(AB27/12%*8.33%,0) -> 1029 | AF27: =+AB27-AE27 -> 454 | AG27: =IF(P27>21000,0,(Y27-X27)*3.25%) -> 401.7 | AH27: 0 | AI27: 0 | AJ27: 0 | AK27: =IF((Y27-X27)>=20001,200,IF((Y27-X27)>=15001,150,0)) -> 0 | AL27: 0 | AM27: =AB27+AD27+AL27 -> 1576 | AN27: =SUM(ROUND((Y27)-(AH27+AI27+AJ27+AK27+AM27),0),0) -> 10784
A28: =A27+1 -> 26 | B28: JAI-383 | C28: 44522 | E28: Anchor | F28: 50100453958441 | G28: HDFC0001635 | H28: 101758031212 | I28: CDNPT0680B | J28: 5217968917 | K28: 35108 | L28: Female | M28: Semi-skilled | N28: No | O28: =VLOOKUP(B28,'Anchor-Attendance'!$B$4:$BB$84,53,0) -> 28 | P28: 12360 | Q28: =P28/$O$1*O28 -> 12360 | R28: =Q28*100% -> 12360 | S28: 0 | T28: 0 | U28: 0 | V28: =ROUND(SUM(R28:U28),0) -> 12360 | W28: 0 | X28: 0 | Y28: =SUM(V28:X28) -> 12360 | Z28: =ROUND(SUM(R28:U28)-S28,0) -> 12360 | AA28: =ROUND(IF(Z28>15000,15000,Z28),0) -> 12360 | AB28: =ROUND(IF(Z28>15000,1800,Z28*12%),0) -> 1483 | AC28: 0 | AD28: =ROUNDUP(IF(P28>21000,0,(Y28-X28)*0.75%),0) -> 93 | AE28: =ROUND(AB28/12%*8.33%,0) -> 1029 | AF28: =+AB28-AE28 -> 454 | AG28: =IF(P28>21000,0,(Y28-X28)*3.25%) -> 401.7 | AH28: 0 | AI28: 0 | AJ28: 0 | AK28: =IF((Y28-X28)>=20001,200,IF((Y28-X28)>=15001,150,0)) -> 0 | AL28: 0 | AM28: =AB28+AD28+AL28 -> 1576 | AN28: =SUM(ROUND((Y28)-(AH28+AI28+AJ28+AK28+AM28),0),0) -> 10784
A29: =A28+1 -> 27 | B29: JAI-394 | C29: 44522 | E29: Anchor | F29: 50100453957613 | G29: HDFC0001635 | H29: 101758038715 | I29: NPKPS3503A | J29: 5217971852 | K29: 36481 | L29: Female | M29: Semi-skilled | N29: No | O29: =VLOOKUP(B29,'Anchor-Attendance'!$B$4:$BB$84,53,0) -> 28 | P29: 12360 | Q29: =P29/$O$1*O29 -> 12360 | R29: =Q29*100% -> 12360 | S29: 0 | T29: 0 | U29: 0 | V29: =ROUND(SUM(R29:U29),0) -> 12360 | W29: 0 | X29: 0 | Y29: =SUM(V29:X29) -> 12360 | Z29: =ROUND(SUM(R29:U29)-S29,0) -> 12360 | AA29: =ROUND(IF(Z29>15000,15000,Z29),0) -> 12360 | AB29: =ROUND(IF(Z29>15000,1800,Z29*12%),0) -> 1483 | AC29: 0 | AD29: =ROUNDUP(IF(P29>21000,0,(Y29-X29)*0.75%),0) -> 93 | AE29: =ROUND(AB29/12%*8.33%,0) -> 1029 | AF29: =+AB29-AE29 -> 454 | AG29: =IF(P29>21000,0,(Y29-X29)*3.25%) -> 401.7 | AH29: 0 | AI29: 0 | AJ29: 0 | AK29: =IF((Y29-X29)>=20001,200,IF((Y29-X29)>=15001,150,0)) -> 0 | AL29: 0 | AM29: =AB29+AD29+AL29 -> 1576 | AN29: =SUM(ROUND((Y29)-(AH29+AI29+AJ29+AK29+AM29),0),0) -> 10784
A30: =A29+1 -> 28 | B30: JAI-470 | C30: 44845 | E30: Anchor | F30: 50100515744043 | G30: HDFC0009087 | H30: 101877719011 | I30: DNJPG4658D | J30: 5218492977 | K30: 36958 | L30: Female | M30: Semi-skilled | N30: =VLOOKUP(B30,'Anchor-Attendance'!$B$4:$K$84,10,0) -> 46076 | O30: =VLOOKUP(B30,'Anchor-Attendance'!$B$4:$BB$84,53,0) -> 13.5 | P30: 12360 | Q30: =P30/$O$1*O30 -> 5959.2857 | R30: =Q30*100% -> 5959.2857 | S30: =Q30*0% -> 0 | T30: 0 | U30: 0 | V30: =ROUND(SUM(R30:U30),0) -> 5959 | W30: =12360-V30 -> 6401 | X30: =AR30 -> 0 | Y30: =SUM(V30:X30) -> 12360 | Z30: =ROUND(SUM(R30:U30)-S30,0) -> 5959 | AA30: =ROUND(IF(Z30>15000,15000,Z30),0) -> 5959 | AB30: =ROUND(IF(Z30>15000,1800,Z30*12%),0) -> 715 | AC30: 0 | AD30: =ROUNDUP(IF(P30>21000,0,(Y30-X30)*0.75%),0) -> 93 | AE30: =ROUND(AB30/12%*8.33%,0) -> 496 | AF30: =+AB30-AE30 -> 219 | AG30: =IF(P30>21000,0,(Y30-X30)*3.25%) -> 401.7 | AH30: 0 | AI30: 0 | AJ30: 0 | AK30: =IF((Y30-X30)>=20001,200,IF((Y30-X30)>=15001,150,0)) -> 0 | AL30: 0 | AM30: =AB30+AD30+AL30 -> 808 | AN30: =SUM(ROUND((Y30)-(AH30+AI30+AJ30+AK30+AM30),0),0) -> 11552 | AO30: Full month salary to be paid | AP30: =ROUND((N30-C30)/365,0) -> 3
A31: =A30+1 -> 29 | B31: JAI-502 | C31: 44845 | E31: Anchor | F31: 50100515744501 | G31: HDFC0009087 | H31: 101877718954 | I31: KZLPS3922P | J31: 5218511775 | K31: 35316 | L31: Female | M31: Semi-skilled | N31: No | O31: =VLOOKUP(B31,'Anchor-Attendance'!$B$4:$BB$84,53,0) -> 28 | P31: 12360 | Q31: =P31/$O$1*O31 -> 12360 | R31: =Q31*100% -> 12360 | S31: 0 | T31: 0 | U31: 0 | V31: =ROUND(SUM(R31:U31),0) -> 12360 | W31: 0 | X31: 0 | Y31: =SUM(V31:X31) -> 12360 | Z31: =ROUND(SUM(R31:U31)-S31,0) -> 12360 | AA31: =ROUND(IF(Z31>15000,15000,Z31),0) -> 12360 | AB31: =ROUND(IF(Z31>15000,1800,Z31*12%),0) -> 1483 | AC31: 0 | AD31: =ROUNDUP(IF(P31>21000,0,(Y31-X31)*0.75%),0) -> 93 | AE31: =ROUND(AB31/12%*8.33%,0) -> 1029 | AF31: =+AB31-AE31 -> 454 | AG31: =IF(P31>21000,0,(Y31-X31)*3.25%) -> 401.7 | AH31: 0 | AI31: 0 | AJ31: 0 | AK31: =IF((Y31-X31)>=20001,200,IF((Y31-X31)>=15001,150,0)) -> 0 | AL31: 0 | AM31: =AB31+AD31+AL31 -> 1576 | AN31: =SUM(ROUND((Y31)-(AH31+AI31+AJ31+AK31+AM31),0),0) -> 10784
A32: =A31+1 -> 30 | B32: JAI-725 | C32: 44909 | E32: Anchor | F32: 50100593151791 | G32: HDFC0001635 | H32: 101907229534 | I32: HFLPP7604N | J32: 5219228476 | K32: 36246 | L32: Female | M32: Semi-skilled | N32: No | O32: =VLOOKUP(B32,'Anchor-Attendance'!$B$4:$BB$84,53,0) -> 28 | P32: 12360 | Q32: =P32/$O$1*O32 -> 12360 | R32: =Q32*100% -> 12360 | S32: 0 | T32: 0 | U32: 0 | V32: =ROUND(SUM(R32:U32),0) -> 12360 | W32: 0 | X32: 0 | Y32: =SUM(V32:X32) -> 12360 | Z32: =ROUND(SUM(R32:U32)-S32,0) -> 12360 | AA32: =ROUND(IF(Z32>15000,15000,Z32),0) -> 12360 | AB32: =ROUND(IF(Z32>15000,1800,Z32*12%),0) -> 1483 | AC32: 0 | AD32: =ROUNDUP(IF(P32>21000,0,(Y32-X32)*0.75%),0) -> 93 | AE32: =ROUND(AB32/12%*8.33%,0) -> 1029 | AF32: =+AB32-AE32 -> 454 | AG32: =IF(P32>21000,0,(Y32-X32)*3.25%) -> 401.7 | AH32: 0 | AI32: 0 | AJ32: 0 | AK32: =IF((Y32-X32)>=20001,200,IF((Y32-X32)>=15001,150,0)) -> 0 | AL32: 0 | AM32: =AB32+AD32+AL32 -> 1576 | AN32: =SUM(ROUND((Y32)-(AH32+AI32+AJ32+AK32+AM32),0),0) -> 10784
A33: =A32+1 -> 31 | B33: JAI-747 | C33: 44909 | E33: AMIA | F33: 50100588150401 | G33: HDFC0001635 | H33: 101907229552 | I33: BIGPY4450F | J33: 5219233496 | K33: 37765 | L33: Female | M33: Semi-skilled | N33: No | O33: =VLOOKUP(B33,'Anchor-Attendance'!$B$4:$BB$84,53,0) -> 28 | P33: 17000 | Q33: =P33/$O$1*O33 -> 17000 | R33: =Q33*90% -> 15300 | S33: =Q33*10% -> 1700 | T33: 0 | U33: 0 | V33: =ROUND(SUM(R33:U33),0) -> 17000 | W33: 0 | X33: 0 | Y33: =SUM(V33:X33) -> 17000 | Z33: =ROUND(SUM(R33:U33)-S33,0) -> 15300 | AA33: =ROUND(IF(Z33>15000,15000,Z33),0) -> 15000 | AB33: =ROUND(IF(Z33>15000,1800,Z33*12%),0) -> 1800 | AC33: 0 | AD33: =ROUNDUP(IF(P33>21000,0,(Y33-X33)*0.75%),0) -> 128 | AE33: =ROUND(AB33/12%*8.33%,0) -> 1250 | AF33: =+AB33-AE33 -> 550 | AG33: =IF(P33>21000,0,(Y33-X33)*3.25%) -> 552.5 | AH33: 0 | AI33: 0 | AJ33: 0 | AK33: =IF((Y33-X33)>=20001,200,IF((Y33-X33)>=15001,150,0)) -> 150 | AL33: 0 | AM33: =AB33+AD33+AL33 -> 1928 | AN33: =SUM(ROUND((Y33)-(AH33+AI33+AJ33+AK33+AM33),0),0) -> 14922
A34: =A33+1 -> 32 | B34: JAI-860 | C34: 45033 | E34: AMIA | F34: 50100593127712 | G34: HDFC0001635 | H34: 101926502058 | I34: EWPPA0721P | J34: 5219251248 | K34: 37795 | L34: Female | M34: Semi-skilled | N34: No | O34: =VLOOKUP(B34,'Anchor-Attendance'!$B$4:$BB$84,53,0) -> 28 | P34: 17000 | Q34: =P34/$O$1*O34 -> 17000 | R34: =Q34*90% -> 15300 | S34: =Q34*10% -> 1700 | T34: 0 | U34: 0 | V34: =ROUND(SUM(R34:U34),0) -> 17000 | W34: 0 | X34: 0 | Y34: =SUM(V34:X34) -> 17000 | Z34: =ROUND(SUM(R34:U34)-S34,0) -> 15300 | AA34: =ROUND(IF(Z34>15000,15000,Z34),0) -> 15000 | AB34: =ROUND(IF(Z34>15000,1800,Z34*12%),0) -> 1800 | AC34: 0 | AD34: =ROUNDUP(IF(P34>21000,0,(Y34-X34)*0.75%),0) -> 128 | AE34: =ROUND(AB34/12%*8.33%,0) -> 1250 | AF34: =+AB34-AE34 -> 550 | AG34: =IF(P34>21000,0,(Y34-X34)*3.25%) -> 552.5 | AH34: 0 | AI34: 0 | AJ34: 0 | AK34: =IF((Y34-X34)>=20001,200,IF((Y34-X34)>=15001,150,0)) -> 150 | AL34: 0 | AM34: =AB34+AD34+AL34 -> 1928 | AN34: =SUM(ROUND((Y34)-(AH34+AI34+AJ34+AK34+AM34),0),0) -> 14922
A35: =A34+1 -> 33 | B35: JAI-1038 | C35: 45033 | E35: Anchor | F35: 50100594492073 | G35: HDFC0009087 | H35: 101916216840 | I35: QMTPS7428R | J35: 5219301318 | K35: 37261 | L35: Female | M35: Semi-skilled | N35: No | O35: =VLOOKUP(B35,'Anchor-Attendance'!$B$4:$BB$84,53,0) -> 28 | P35: 12360 | Q35: =P35/$O$1*O35 -> 12360 | R35: =Q35*100% -> 12360 | S35: 0 | T35: 0 | U35: 0 | V35: =ROUND(SUM(R35:U35),0) -> 12360 | W35: 0 | X35: 0 | Y35: =SUM(V35:X35) -> 12360 | Z35: =ROUND(SUM(R35:U35)-S35,0) -> 12360 | AA35: =ROUND(IF(Z35>15000,15000,Z35),0) -> 12360 | AB35: =ROUND(IF(Z35>15000,1800,Z35*12%),0) -> 1483 | AC35: 0 | AD35: =ROUNDUP(IF(P35>21000,0,(Y35-X35)*0.75%),0) -> 93 | AE35: =ROUND(AB35/12%*8.33%,0) -> 1029 | AF35: =+AB35-AE35 -> 454 | AG35: =IF(P35>21000,0,(Y35-X35)*3.25%) -> 401.7 | AH35: 0 | AI35: 0 | AJ35: 0 | AK35: =IF((Y35-X35)>=20001,200,IF((Y35-X35)>=15001,150,0)) -> 0 | AL35: 0 | AM35: =AB35+AD35+AL35 -> 1576 | AN35: =SUM(ROUND((Y35)-(AH35+AI35+AJ35+AK35+AM35),0),0) -> 10784
A36: =A35+1 -> 34 | B36: JAI-1121 | C36: 45086 | E36: Anchor | F36: 50100662377172 | G36: HDFC0009087 | H36: 101970000680 | I36: IGSPM9947Q | J36: 5219753348 | K36: 37735 | L36: Female | M36: Semi-skilled | N36: No | O36: =VLOOKUP(B36,'Anchor-Attendance'!$B$4:$BB$84,53,0) -> 28 | P36: 12360 | Q36: =P36/$O$1*O36 -> 12360 | R36: =Q36*100% -> 12360 | S36: 0 | T36: 0 | U36: 0 | V36: =ROUND(SUM(R36:U36),0) -> 12360 | W36: 0 | X36: 0 | Y36: =SUM(V36:X36) -> 12360 | Z36: =ROUND(SUM(R36:U36)-S36,0) -> 12360 | AA36: =ROUND(IF(Z36>15000,15000,Z36),0) -> 12360 | AB36: =ROUND(IF(Z36>15000,1800,Z36*12%),0) -> 1483 | AC36: 0 | AD36: =ROUNDUP(IF(P36>21000,0,(Y36-X36)*0.75%),0) -> 93 | AE36: =ROUND(AB36/12%*8.33%,0) -> 1029 | AF36: =+AB36-AE36 -> 454 | AG36: =IF(P36>21000,0,(Y36-X36)*3.25%) -> 401.7 | AH36: 0 | AI36: 0 | AJ36: 0 | AK36: =IF((Y36-X36)>=20001,200,IF((Y36-X36)>=15001,150,0)) -> 0 | AL36: 0 | AM36: =AB36+AD36+AL36 -> 1576 | AN36: =SUM(ROUND((Y36)-(AH36+AI36+AJ36+AK36+AM36),0),0) -> 10784
A37: =A36+1 -> 35 | B37: JAI-1136 | C37: 45086 | E37: Anchor | F37: 50100662377376 | G37: HDFC0009087 | H37: 101970000410 | I37: GMGPR3649J | J37: 5219753019 | K37: 37846 | L37: Female | M37: Semi-skilled | N37: No | O37: =VLOOKUP(B37,'Anchor-Attendance'!$B$4:$BB$84,53,0) -> 27.5 | P37: 12360 | Q37: =P37/$O$1*O37 -> 12139.286 | R37: =Q37*100% -> 12139.286 | S37: 0 | T37: 0 | U37: 0 | V37: =ROUND(SUM(R37:U37),0) -> 12139 | W37: 0 | X37: 0 | Y37: =SUM(V37:X37) -> 12139 | Z37: =ROUND(SUM(R37:U37)-S37,0) -> 12139 | AA37: =ROUND(IF(Z37>15000,15000,Z37),0) -> 12139 | AB37: =ROUND(IF(Z37>15000,1800,Z37*12%),0) -> 1457 | AC37: 0 | AD37: =ROUNDUP(IF(P37>21000,0,(Y37-X37)*0.75%),0) -> 92 | AE37: =ROUND(AB37/12%*8.33%,0) -> 1011 | AF37: =+AB37-AE37 -> 446 | AG37: =IF(P37>21000,0,(Y37-X37)*3.25%) -> 394.5175 | AH37: 0 | AI37: 0 | AJ37: 0 | AK37: =IF((Y37-X37)>=20001,200,IF((Y37-X37)>=15001,150,0)) -> 0 | AL37: 0 | AM37: =AB37+AD37+AL37 -> 1549 | AN37: =SUM(ROUND((Y37)-(AH37+AI37+AJ37+AK37+AM37),0),0) -> 10590
A38: =A37+1 -> 36 | B38: JAI-1139 | C38: 45086 | E38: Anchor | F38: 50100662377324 | G38: HDFC0009087 | H38: 101970000447 | I38: NWGPS1152E | J38: 5219753255 | K38: 36644 | L38: Female | M38: Semi-skilled | N38: No | O38: =VLOOKUP(B38,'Anchor-Attendance'!$B$4:$BB$84,53,0) -> 28 | P38: 12360 | Q38: =P38/$O$1*O38 -> 12360 | R38: =Q38*100% -> 12360 | S38: 0 | T38: 0 | U38: 0 | V38: =ROUND(SUM(R38:U38),0) -> 12360 | W38: 0 | X38: 0 | Y38: =SUM(V38:X38) -> 12360 | Z38: =ROUND(SUM(R38:U38)-S38,0) -> 12360 | AA38: =ROUND(IF(Z38>15000,15000,Z38),0) -> 12360 | AB38: =ROUND(IF(Z38>15000,1800,Z38*12%),0) -> 1483 | AC38: 0 | AD38: =ROUNDUP(IF(P38>21000,0,(Y38-X38)*0.75%),0) -> 93 | AE38: =ROUND(AB38/12%*8.33%,0) -> 1029 | AF38: =+AB38-AE38 -> 454 | AG38: =IF(P38>21000,0,(Y38-X38)*3.25%) -> 401.7 | AH38: 0 | AI38: 0 | AJ38: 0 | AK38: =IF((Y38-X38)>=20001,200,IF((Y38-X38)>=15001,150,0)) -> 0 | AL38: 0 | AM38: =AB38+AD38+AL38 -> 1576 | AN38: =SUM(ROUND((Y38)-(AH38+AI38+AJ38+AK38+AM38),0),0) -> 10784
A39: =A38+1 -> 37 | B39: JAI-1145 | C39: 45086 | E39: Anchor | F39: 50100613610990 | G39: HDFC0001635 | H39: 101969999988 | I39: NKMPK1037C | J39: 5219754257 | K39: 37266 | L39: Female | M39: Semi-skilled | N39: No | O39: =VLOOKUP(B39,'Anchor-Attendance'!$B$4:$BB$84,53,0) -> 28 | P39: 12360 | Q39: =P39/$O$1*O39 -> 12360 | R39: =Q39*100% -> 12360 | S39: =Q39*0% -> 0 | T39: 0 | U39: 0 | V39: =ROUND(SUM(R39:U39),0) -> 12360 | W39: 0 | X39: 0 | Y39: =SUM(V39:X39) -> 12360 | Z39: =ROUND(SUM(R39:U39)-S39,0) -> 12360 | AA39: =ROUND(IF(Z39>15000,15000,Z39),0) -> 12360 | AB39: =ROUND(IF(Z39>15000,1800,Z39*12%),0) -> 1483 | AC39: 0 | AD39: =ROUNDUP(IF(P39>21000,0,(Y39-X39)*0.75%),0) -> 93 | AE39: =ROUND(AB39/12%*8.33%,0) -> 1029 | AF39: =+AB39-AE39 -> 454 | AG39: =IF(P39>21000,0,(Y39-X39)*3.25%) -> 401.7 | AH39: 0 | AI39: 0 | AJ39: 0 | AK39: =IF((Y39-X39)>=20001,200,IF((Y39-X39)>=15001,150,0)) -> 0 | AL39: 0 | AM39: =AB39+AD39+AL39 -> 1576 | AN39: =SUM(ROUND((Y39)-(AH39+AI39+AJ39+AK39+AM39),0),0) -> 10784
A40: =A39+1 -> 38 | B40: JAI-1149 | C40: 45086 | E40: Anchor | F40: 50100662377248 | G40: HDFC0009087 | H40: 101970000423 | I40: PZFPS2268D | J40: 5219755347 | K40: 37084 | L40: Female | M40: Semi-skilled | N40: No | O40: =VLOOKUP(B40,'Anchor-Attendance'!$B$4:$BB$84,53,0) -> 28 | P40: 12360 | Q40: =P40/$O$1*O40 -> 12360 | R40: =Q40*100% -> 12360 | S40: 0 | T40: 0 | U40: 0 | V40: =ROUND(SUM(R40:U40),0) -> 12360 | W40: 0 | X40: 0 | Y40: =SUM(V40:X40) -> 12360 | Z40: =ROUND(SUM(R40:U40)-S40,0) -> 12360 | AA40: =ROUND(IF(Z40>15000,15000,Z40),0) -> 12360 | AB40: =ROUND(IF(Z40>15000,1800,Z40*12%),0) -> 1483 | AC40: 0 | AD40: =ROUNDUP(IF(P40>21000,0,(Y40-X40)*0.75%),0) -> 93 | AE40: =ROUND(AB40/12%*8.33%,0) -> 1029 | AF40: =+AB40-AE40 -> 454 | AG40: =IF(P40>21000,0,(Y40-X40)*3.25%) -> 401.7 | AH40: 0 | AI40: 0 | AJ40: 0 | AK40: =IF((Y40-X40)>=20001,200,IF((Y40-X40)>=15001,150,0)) -> 0 | AL40: 0 | AM40: =AB40+AD40+AL40 -> 1576 | AN40: =SUM(ROUND((Y40)-(AH40+AI40+AJ40+AK40+AM40),0),0) -> 10784
...

Sheet Anchor-Attendance
D1: Customer | E1: Project | F1: Sub Project | G1: Work Location | H1: Mobile Numbers | I1: Mail Id's | J1: Jukshio DOJ | K1: DOE | L1: Sun | M1: Mon | N1: Tue | O1: Wed | P1: Thu | Q1: Fri | R1: Sat | S1: Sun | T1: Mon | U1: Tue | V1: Wed | W1: Thu | X1: Fri | Y1: Sat | Z1: Sun | AA1: Mon | AB1: Tue | AC1: Wed | AD1: Thu | AE1: Fri | AF1: Sat | AG1: Sun | AH1: Mon | AI1: Tue | AJ1: Wed | AK1: Thu | AL1: Fri | AM1: Sat | AN1: TD | AO1: W/O | AP1: L | AQ1: HFL | AR1: H | AS1: MG | AT1: ML | AU1: UL | AV1: MC | AW1: BL | AX1: MDL | AY1: LOP | AZ1: TD | BD1: November Opening leaves | BJ1: Present month leave utilization | BP1: Closing Leaves
A2: S.NO | B2: EMP ID | C2: Names | L2: 1 | M2: 2 | N2: 3 | O2: 4 | P2: 5 | Q2: 6 | R2: 7 | S2: 8 | T2: 9 | U2: 10 | V2: 11 | W2: 12 | X2: 13 | Y2: 14 | Z2: 15 | AA2: 16 | AB2: 17 | AC2: 18 | AD2: 19 | AE2: 20 | AF2: 21 | AG2: 22 | AH2: 23 | AI2: 24 | AJ2: 25 | AK2: 26 | AL2: 27 | AM2: 28 | AN2: Total Present | AO2: Total Week Offs | AP2: Total Leaves | AQ2: Total Half Day Leaves | AR2: Holiday | AS2: Marriage | AT2: Maternity Leave | AU2: UnPaid Leave | AV2: Misscarriage | AW2: Bereavement Leaves | AX2: Medical Leave | AY2: Loss of Pay | AZ2: Total Days | BA2: Total Actual Days | BB2: Total Payable Days | BC2: Total % | BD2: Last Year Carry Forward Leave's | BE2: CL | BF2: SL | BG2: EL | BH2: MG | BI2: Extra EL Balance | BJ2: Last Year Carry Forward Leave's | BK2: CL | BL2: SL | BM2: EL | BN2: MG | BO2: Lop | BP2: Last Year Carry Forward Leave's | BQ2: CL | BR2: SL | BS2: EL | BT2: MG | BU2: Extra EL Balance | BV2: Feb'26 Attendance Comments | BW2: Jan'26 Attendance Comments
BE3: 0.5 | BF3: 0.5 | BG3: 1 | BI3: 0.25
A4: 1 | B4: JAI-148 | D4: Manappuram/Muthoot/Bajaj | E4: KYC | F4: Birdman | G4: Suvali | H4: 8688615667 | I4: poojitha.gundlapalli@jukshio.com | J4: 44075 | L4: W/O | M4: P | N4: P | O4: P | P4: P | Q4: P | R4: P | S4: W/O | T4: P | U4: P | V4: P | W4: P | X4: P | Y4: W/O | Z4: P | AA4: P | AB4: P | AC4: P | AD4: P | AE4: P | AF4: P | AG4: W/O | AH4: P | AI4: P | AJ4: W/O | AK4: P | AL4: P | AM4: P | AN4: =COUNTIF(L4:AM4,"P")+COUNTIF(L4:AM4,"HFL")/2 -> 23 | AO4: =COUNTIF(L4:AM4,"W/O") -> 5 | AP4: =COUNTIF(L4:AM4,"L") -> 0 | AQ4: =COUNTIF(L4:AM4,"HFL")/2 -> 0 | AR4: =COUNTIF(L4:AM4,"H") -> 0 | AS4: =COUNTIF(L4:AM4,"MG") -> 0 | AT4: =COUNTIF(L4:AM4,"ML") -> 0 | AU4: =COUNTIF(L4:AM4,"UL") -> 0 | AV4: =COUNTIF(L4:AM4,"MC") -> 0 | AW4: =COUNTIF(L4:AM4,"BL") -> 0 | AX4: =COUNTIF(L4:AM4,"MDL") -> 0 | AY4: =COUNTIF(L4:AM4,"LOP") -> 0 | AZ4: =SUM(AN4:AY4) -> 28 | BA4: =SUM(AP4:AQ4,AS4:AY4,AN4) -> 23 | BB4: =AZ4-(AU4+BO4) -> 28 | BC4: =AN4/BA4 -> 1 | BD4: =VLOOKUP(B4,'Jan''26- Leave Bal'!$B$3:$D$83,3,0) -> 0 | BE4: =VLOOKUP(B4,'Jan''26- Leave Bal'!$B$3:$E$83,4,0)+$BE$3 -> 1 | BF4: =VLOOKUP(B4,'Jan''26- Leave Bal'!$B$3:$F$83,5,0)+$BF$3 -> 2.5 | BG4: =VLOOKUP(B4,'Jan''26- Leave Bal'!$B$3:$G$83,6,0)+$BG$3 -> 13 | BH4: =VLOOKUP(B4,'Jan''26- Leave Bal'!$B$3:$H$83,7,0) -> 15 | BI4: =VLOOKUP(B4,'Jan''26- Leave Bal'!$B$3:$I$83,8,0)+$BI$3 -> 0.75 | BJ4: =IF((AP4+AQ4)<=BD4, (AP4+AQ4),BD4) -> 0 | BK4: =IF(((AP4+AQ4)-BJ4)>BE4,BE4,(AP4+AQ4)-BJ4) -> 0 | BL4: =IF((AP4+AQ4-BJ4-BK4)>=BF4,BF4,(AP4+AQ4-BJ4-BK4)) -> 0 | BM4: =IF((AP4+AQ4-BJ4-BK4-BL4)>=BG4,BG4,(AP4+AQ4-BJ4-BK4-BL4)) -> 0 | BN4: =AS4 -> 0 | BO4: =AP4+AQ4-BJ4-BK4-BL4-BM4 -> 0 | BP4: =BD4-BJ4 -> 0 | BQ4: =BE4-BK4 -> 1 | BR4: =BF4-BL4 -> 2.5 | BS4: =BG4-BM4 -> 13 | BT4: =BH4-BN4 -> 15 | BU4: =BI4 -> 0.75 | BV4: 01st Mar weekoff taken in Feb Last week itself | BW4: 0
A5: 2 | B5: JAI-394 | D5: Manappuram/Muthoot/Bajaj | E5: KYC | F5: Birdman | G5: Suvali | H5: 7995932074 | I5: swathi.baddam@jukshio.com | J5: 44522 | L5: W/O | M5: P | N5: P | O5: P | P5: P | Q5: P | R5: W/O | S5: P | T5: P | U5: P | V5: P | W5: P | X5: P | Y5: P | Z5: W/O | AA5: P | AB5: P | AC5: P | AD5: P | AE5: P | AF5: W/O | AG5: P | AH5: P | AI5: P | AJ5: P | AK5: P | AL5: P | AM5: P | AN5: =COUNTIF(L5:AM5,"P")+COUNTIF(L5:AM5,"HFL")/2 -> 24 | AO5: =COUNTIF(L5:AM5,"W/O") -> 4 | AP5: =COUNTIF(L5:AM5,"L") -> 0 | AQ5: =COUNTIF(L5:AM5,"HFL")/2 -> 0 | AR5: =COUNTIF(L5:AM5,"H") -> 0 | AS5: =COUNTIF(L5:AM5,"MG") -> 0 | AT5: =COUNTIF(L5:AM5,"ML") -> 0 | AU5: =COUNTIF(L5:AM5,"UL") -> 0 | AV5: =COUNTIF(L5:AM5,"MC") -> 0 | AW5: =COUNTIF(L5:AM5,"BL") -> 0 | AX5: =COUNTIF(L5:AM5,"MDL") -> 0 | AY5: =COUNTIF(L5:AM5,"LOP") -> 0 | AZ5: =SUM(AN5:AY5) -> 28 | BA5: =SUM(AP5:AQ5,AS5:AY5,AN5) -> 24 | BB5: =AZ5-(AU5+BO5) -> 28 | BC5: =AN5/BA5 -> 1 | BD5: =VLOOKUP(B5,'Jan''26- Leave Bal'!$B$3:$D$83,3,0) -> 0 | BE5: =VLOOKUP(B5,'Jan''26- Leave Bal'!$B$3:$E$83,4,0)+$BE$3 -> 0.5 | BF5: =VLOOKUP(B5,'Jan''26- Leave Bal'!$B$3:$F$83,5,0)+$BF$3 -> 0.5 | BG5: =VLOOKUP(B5,'Jan''26- Leave Bal'!$B$3:$G$83,6,0)+$BG$3 -> 6.5 | BH5: =VLOOKUP(B5,'Jan''26- Leave Bal'!$B$3:$H$83,7,0) -> 15 | BI5: =VLOOKUP(B5,'Jan''26- Leave Bal'!$B$3:$I$83,8,0)+$BI$3 -> 0.75 | BJ5: =IF((AP5+AQ5)<=BD5, (AP5+AQ5),BD5) -> 0 | BK5: =IF(((AP5+AQ5)-BJ5)>BE5,BE5,(AP5+AQ5)-BJ5) -> 0 | BL5: =IF((AP5+AQ5-BJ5-BK5)>=BF5,BF5,(AP5+AQ5-BJ5-BK5)) -> 0 | BM5: =IF((AP5+AQ5-BJ5-BK5-BL5)>=BG5,BG5,(AP5+AQ5-BJ5-BK5-BL5)) -> 0 | BN5: =AS5 -> 0 | BO5: =AP5+AQ5-BJ5-BK5-BL5-BM5 -> 0 | BP5: =BD5-BJ5 -> 0 | BQ5: =BE5-BK5 -> 0.5 | BR5: =BF5-BL5 -> 0.5 | BS5: =BG5-BM5 -> 6.5 | BT5: =BH5-BN5 -> 15 | BU5: =BI5 -> 0.75 | BW5: 0
A6: 3 | B6: JAI-502 | D6: Manappuram/Muthoot/Bajaj | E6: KYC | F6: Birdman | G6: Suvali | H6: 9052853216 | I6: balajyothi.somana@jukshio.com | J6: 44845 | L6: P | M6: P | N6: P | O6: HFL | P6: L | Q6: P | R6: P | S6: W/O | T6: P | U6: P | V6: P | W6: P | X6: P | Y6: W/O | Z6: P | AA6: P | AB6: P | AC6: P | AD6: P | AE6: P | AF6: P | AG6: W/O | AH6: P | AI6: P | AJ6: W/O | AK6: P | AL6: P | AM6: P | AN6: =COUNTIF(L6:AM6,"P")+COUNTIF(L6:AM6,"HFL")/2 -> 22.5 | AO6: =COUNTIF(L6:AM6,"W/O") -> 4 | AP6: =COUNTIF(L6:AM6,"L") -> 1 | AQ6: =COUNTIF(L6:AM6,"HFL")/2 -> 0.5 | AR6: =COUNTIF(L6:AM6,"H") -> 0 | AS6: =COUNTIF(L6:AM6,"MG") -> 0 | AT6: =COUNTIF(L6:AM6,"ML") -> 0 | AU6: =COUNTIF(L6:AM6,"UL") -> 0 | AV6: =COUNTIF(L6:AM6,"MC") -> 0 | AW6: =COUNTIF(L6:AM6,"BL") -> 0 | AX6: =COUNTIF(L6:AM6,"MDL") -> 0 | AY6: =COUNTIF(L6:AM6,"LOP") -> 0 | AZ6: =SUM(AN6:AY6) -> 28 | BA6: =SUM(AP6:AQ6,AS6:AY6,AN6) -> 24 | BB6: =AZ6-(AU6+BO6) -> 28 | BC6: =AN6/BA6 -> 0.9375 | BD6: =VLOOKUP(B6,'Jan''26- Leave Bal'!$B$3:$D$83,3,0) -> 0 | BE6: =VLOOKUP(B6,'Jan''26- Leave Bal'!$B$3:$E$83,4,0)+$BE$3 -> 0.5 | BF6: =VLOOKUP(B6,'Jan''26- Leave Bal'!$B$3:$F$83,5,0)+$BF$3 -> 0.5 | BG6: =VLOOKUP(B6,'Jan''26- Leave Bal'!$B$3:$G$83,6,0)+$BG$3 -> 6.5 | BH6: =VLOOKUP(B6,'Jan''26- Leave Bal'!$B$3:$H$83,7,0) -> 15 | BI6: =VLOOKUP(B6,'Jan''26- Leave Bal'!$B$3:$I$83,8,0)+$BI$3 -> 0.75 | BJ6: =IF((AP6+AQ6)<=BD6, (AP6+AQ6),BD6) -> 0 | BK6: =IF(((AP6+AQ6)-BJ6)>BE6,BE6,(AP6+AQ6)-BJ6) -> 0.5 | BL6: =IF((AP6+AQ6-BJ6-BK6)>=BF6,BF6,(AP6+AQ6-BJ6-BK6)) -> 0.5 | BM6: =IF((AP6+AQ6-BJ6-BK6-BL6)>=BG6,BG6,(AP6+AQ6-BJ6-BK6-BL6)) -> 0.5 | BN6: =AS6 -> 0 | BO6: =AP6+AQ6-BJ6-BK6-BL6-BM6 -> 0 | BP6: =BD6-BJ6 -> 0 | BQ6: =BE6-BK6 -> 0 | BR6: =BF6-BL6 -> 0 | BS6: =BG6-BM6 -> 6 | BT6: =BH6-BN6 -> 15 | BU6: =BI6 -> 0.75 | BV6: 01st Mar weekoff taken in Feb Last week itself | BW6: 01st feb Weekoff taken early in Jan'26
A7: 4 | B7: JAI-098 | D7: Manappuram/Muthoot/Bajaj | E7: KYC | F7: Birdman | G7: Suvali | H7: 9381993843 | I7: parijatha.paka@jukshio.com | J7: 43983 | L7: P | M7: P | N7: W/O | O7: L | P7: P | Q7: P | R7: P | S7: P | T7: P | U7: P | V7: P | W7: P | X7: W/O | Y7: P | Z7: P | AA7: P | AB7: P | AC7: W/O | AD7: P | AE7: P | AF7: L | AG7: P | AH7: P | AI7: P | AJ7: P | AK7: P | AL7: P | AM7: P | AN7: =COUNTIF(L7:AM7,"P")+COUNTIF(L7:AM7,"HFL")/2 -> 23 | AO7: =COUNTIF(L7:AM7,"W/O") -> 3 | AP7: =COUNTIF(L7:AM7,"L") -> 2 | AQ7: =COUNTIF(L7:AM7,"HFL")/2 -> 0 | AR7: =COUNTIF(L7:AM7,"H") -> 0 | AS7: =COUNTIF(L7:AM7,"MG") -> 0 | AT7: =COUNTIF(L7:AM7,"ML") -> 0 | AU7: =COUNTIF(L7:AM7,"UL") -> 0 | AV7: =COUNTIF(L7:AM7,"MC") -> 0 | AW7: =COUNTIF(L7:AM7,"BL") -> 0 | AX7: =COUNTIF(L7:AM7,"MDL") -> 0 | AY7: =COUNTIF(L7:AM7,"LOP") -> 0 | AZ7: =SUM(AN7:AY7) -> 28 | BA7: =SUM(AP7:AQ7,AS7:AY7,AN7) -> 25 | BB7: =AZ7-(AU7+BO7) -> 28 | BC7: =AN7/BA7 -> 0.92 | BD7: =VLOOKUP(B7,'Jan''26- Leave Bal'!$B$3:$D$83,3,0) -> 0 | BE7: =VLOOKUP(B7,'Jan''26- Leave Bal'!$B$3:$E$83,4,0)+$BE$3 -> 0.5 | BF7: =VLOOKUP(B7,'Jan''26- Leave Bal'!$B$3:$F$83,5,0)+$BF$3 -> 0.5 | BG7: =VLOOKUP(B7,'Jan''26- Leave Bal'!$B$3:$G$83,6,0)+$BG$3 -> 1 | BH7: =VLOOKUP(B7,'Jan''26- Leave Bal'!$B$3:$H$83,7,0) -> 15 | BI7: =VLOOKUP(B7,'Jan''26- Leave Bal'!$B$3:$I$83,8,0)+$BI$3 -> 0.75 | BJ7: =IF((AP7+AQ7)<=BD7, (AP7+AQ7),BD7) -> 0 | BK7: =IF(((AP7+AQ7)-BJ7)>BE7,BE7,(AP7+AQ7)-BJ7) -> 0.5 | BL7: =IF((AP7+AQ7-BJ7-BK7)>=BF7,BF7,(AP7+AQ7-BJ7-BK7)) -> 0.5 | BM7: =IF((AP7+AQ7-BJ7-BK7-BL7)>=BG7,BG7,(AP7+AQ7-BJ7-BK7-BL7)) -> 1 | BN7: =AS7 -> 0 | BO7: =AP7+AQ7-BJ7-BK7-BL7-BM7 -> 0 | BP7: =BD7-BJ7 -> 0 | BQ7: =BE7-BK7 -> 0 | BR7: =BF7-BL7 -> 0 | BS7: =BG7-BM7 -> 0 | BT7: =BH7-BN7 -> 15 | BU7: =BI7 -> 0.75 | BW7: 01st feb Weekoff taken early in Jan'26
A8: 5 | B8: JAI-265 | D8: Manappuram/Muthoot/Bajaj | E8: KYC | F8: Birdman | G8: Suvali | H8: 9381626507 | I8: shravya.busha@jukshio.com | J8: 44326 | L8: HFL | M8: W/O | N8: P | O8: P | P8: P | Q8: P | R8: P | S8: P | T8: P | U8: P | V8: P | W8: P | X8: P | Y8: P | Z8: W/O | AA8: P | AB8: P | AC8: P | AD8: P | AE8: W/O | AF8: L | AG8: L | AH8: P | AI8: P | AJ8: P | AK8: P | AL8: P | AM8: P | AN8: =COUNTIF(L8:AM8,"P")+COUNTIF(L8:AM8,"HFL")/2 -> 22.5 | AO8: =COUNTIF(L8:AM8,"W/O") -> 3 | AP8: =COUNTIF(L8:AM8,"L") -> 2 | AQ8: =COUNTIF(L8:AM8,"HFL")/2 -> 0.5 | AR8: =COUNTIF(L8:AM8,"H") -> 0 | AS8: =COUNTIF(L8:AM8,"MG") -> 0 | AT8: =COUNTIF(L8:AM8,"ML") -> 0 | AU8: =COUNTIF(L8:AM8,"UL") -> 0 | AV8: =COUNTIF(L8:AM8,"MC") -> 0 | AW8: =COUNTIF(L8:AM8,"BL") -> 0 | AX8: =COUNTIF(L8:AM8,"MDL") -> 0 | AY8: =COUNTIF(L8:AM8,"LOP") -> 0 | AZ8: =SUM(AN8:AY8) -> 28 | BA8: =SUM(AP8:AQ8,AS8:AY8,AN8) -> 25 | BB8: =AZ8-(AU8+BO8) -> 28 | BC8: =AN8/BA8 -> 0.9 | BD8: =VLOOKUP(B8,'Jan''26- Leave Bal'!$B$3:$D$83,3,0) -> 0 | BE8: =VLOOKUP(B8,'Jan''26- Leave Bal'!$B$3:$E$83,4,0)+$BE$3 -> 0.5 | BF8: =VLOOKUP(B8,'Jan''26- Leave Bal'!$B$3:$F$83,5,0)+$BF$3 -> 2.5 | BG8: =VLOOKUP(B8,'Jan''26- Leave Bal'!$B$3:$G$83,6,0)+$BG$3 -> 11 | BH8: =VLOOKUP(B8,'Jan''26- Leave Bal'!$B$3:$H$83,7,0) -> 0 | BI8: =VLOOKUP(B8,'Jan''26- Leave Bal'!$B$3:$I$83,8,0)+$BI$3 -> 0.75 | BJ8: =IF((AP8+AQ8)<=BD8, (AP8+AQ8),BD8) -> 0 | BK8: =IF(((AP8+AQ8)-BJ8)>BE8,BE8,(AP8+AQ8)-BJ8) -> 0.5 | BL8: =IF((AP8+AQ8-BJ8-BK8)>=BF8,BF8,(AP8+AQ8-BJ8-BK8)) -> 2 | BM8: =IF((AP8+AQ8-BJ8-BK8-BL8)>=BG8,BG8,(AP8+AQ8-BJ8-BK8-BL8)) -> 0 | BN8: =AS8 -> 0 | BO8: =AP8+AQ8-BJ8-BK8-BL8-BM8 -> 0 | BP8: =BD8-BJ8 -> 0 | BQ8: =BE8-BK8 -> 0 | BR8: =BF8-BL8 -> 0.5 | BS8: =BG8-BM8 -> 11 | BT8: =BH8-BN8 -> 0 | BU8: =BI8 -> 0.75 | BW8: 01st feb Weekoff taken early in Jan'26
A9: 6 | B9: JAI-382 | D9: Manappuram/Muthoot/Bajaj | E9: KYC | F9: Birdman | G9: Suvali | H9: 90522 62927 | I9: rekha.bommaraju@jukshio.com | J9: 44522 | L9: W/O | M9: P | N9: P | O9: P | P9: W/O | Q9: P | R9: P | S9: P | T9: P | U9: P | V9: P | W9: P | X9: P | Y9: P | Z9: W/O | AA9: P | AB9: P | AC9: L | AD9: P | AE9: W/O | AF9: P | AG9: P | AH9: P | AI9: P | AJ9: W/O | AK9: P | AL9: P | AM9: P | AN9: =COUNTIF(L9:AM9,"P")+COUNTIF(L9:AM9,"HFL")/2 -> 22 | AO9: =COUNTIF(L9:AM9,"W/O") -> 5 | AP9: =COUNTIF(L9:AM9,"L") -> 1 | AQ9: =COUNTIF(L9:AM9,"HFL")/2 -> 0 | AR9: =COUNTIF(L9:AM9,"H") -> 0 | AS9: =COUNTIF(L9:AM9,"MG") -> 0 | AT9: =COUNTIF(L9:AM9,"ML") -> 0 | AU9: =COUNTIF(L9:AM9,"UL") -> 0 | AV9: =COUNTIF(L9:AM9,"MC") -> 0 | AW9: =COUNTIF(L9:AM9,"BL") -> 0 | AX9: =COUNTIF(L9:AM9,"MDL") -> 0 | AY9: =COUNTIF(L9:AM9,"LOP") -> 0 | AZ9: =SUM(AN9:AY9) -> 28 | BA9: =SUM(AP9:AQ9,AS9:AY9,AN9) -> 23 | BB9: =AZ9-(AU9+BO9) -> 28 | BC9: =AN9/BA9 -> 0.95652174 | BD9: =VLOOKUP(B9,'Jan''26- Leave Bal'!$B$3:$D$83,3,0) -> 0 | BE9: =VLOOKUP(B9,'Jan''26- Leave Bal'!$B$3:$E$83,4,0)+$BE$3 -> 0.5 | BF9: =VLOOKUP(B9,'Jan''26- Leave Bal'!$B$3:$F$83,5,0)+$BF$3 -> 0.5 | BG9: =VLOOKUP(B9,'Jan''26- Leave Bal'!$B$3:$G$83,6,0)+$BG$3 -> 5.5 | BH9: =VLOOKUP(B9,'Jan''26- Leave Bal'!$B$3:$H$83,7,0) -> 15 | BI9: =VLOOKUP(B9,'Jan''26- Leave Bal'!$B$3:$I$83,8,0)+$BI$3 -> 0.75 | BJ9: =IF((AP9+AQ9)<=BD9, (AP9+AQ9),BD9) -> 0 | BK9: =IF(((AP9+AQ9)-BJ9)>BE9,BE9,(AP9+AQ9)-BJ9) -> 0.5 | BL9: =IF((AP9+AQ9-BJ9-BK9)>=BF9,BF9,(AP9+AQ9-BJ9-BK9)) -> 0.5 | BM9: =IF((AP9+AQ9-BJ9-BK9-BL9)>=BG9,BG9,(AP9+AQ9-BJ9-BK9-BL9)) -> 0 | BN9: =AS9 -> 0 | BO9: =AP9+AQ9-BJ9-BK9-BL9-BM9 -> 0 | BP9: =BD9-BJ9 -> 0 | BQ9: =BE9-BK9 -> 0 | BR9: =BF9-BL9 -> 0 | BS9: =BG9-BM9 -> 5.5 | BT9: =BH9-BN9 -> 15 | BU9: =BI9 -> 0.75 | BV9: 01st Mar weekoff taken in Feb Last week itself | BW9: 0
A10: 7 | B10: JAI-248 | D10: Manappuram/Muthoot/Bajaj | E10: KYC | F10: Birdman | G10: Suvali | H10: 9014106905 | I10: balamani.dommata@jukshio.com | J10: 44326 | L10: P | M10: P | N10: P | O10: P | P10: P | Q10: P | R10: P | S10: W/O | T10: P | U10: L | V10: W/O | W10: L | X10: P | Y10: P | Z10: P | AA10: P | AB10: P | AC10: P | AD10: P | AE10: P | AF10: P | AG10: W/O | AH10: P | AI10: P | AJ10: P | AK10: P | AL10: P | AM10: P | AN10: =COUNTIF(L10:AM10,"P")+COUNTIF(L10:AM10,"HFL")/2 -> 23 | AO10: =COUNTIF(L10:AM10,"W/O") -> 3 | AP10: =COUNTIF(L10:AM10,"L") -> 2 | AQ10: =COUNTIF(L10:AM10,"HFL")/2 -> 0 | AR10: =COUNTIF(L10:AM10,"H") -> 0 | AS10: =COUNTIF(L10:AM10,"MG") -> 0 | AT10: =COUNTIF(L10:AM10,"ML") -> 0 | AU10: =COUNTIF(L10:AM10,"UL") -> 0 | AV10: =COUNTIF(L10:AM10,"MC") -> 0 | AW10: =COUNTIF(L10:AM10,"BL") -> 0 | AX10: =COUNTIF(L10:AM10,"MDL") -> 0 | AY10: =COUNTIF(L10:AM10,"LOP") -> 0 | AZ10: =SUM(AN10:AY10) -> 28 | BA10: =SUM(AP10:AQ10,AS10:AY10,AN10) -> 25 | BB10: =AZ10-(AU10+BO10) -> 28 | BC10: =AN10/BA10 -> 0.92 | BD10: =VLOOKUP(B10,'Jan''26- Leave Bal'!$B$3:$D$83,3,0) -> 0 | BE10: =VLOOKUP(B10,'Jan''26- Leave Bal'!$B$3:$E$83,4,0)+$BE$3 -> 0.5 | BF10: =VLOOKUP(B10,'Jan''26- Leave Bal'!$B$3:$F$83,5,0)+$BF$3 -> 2 | BG10: =VLOOKUP(B10,'Jan''26- Leave Bal'!$B$3:$G$83,6,0)+$BG$3 -> 13 | BH10: =VLOOKUP(B10,'Jan''26- Leave Bal'!$B$3:$H$83,7,0) -> 15 | BI10: =VLOOKUP(B10,'Jan''26- Leave Bal'!$B$3:$I$83,8,0)+$BI$3 -> 0.75 | BJ10: =IF((AP10+AQ10)<=BD10, (AP10+AQ10),BD10) -> 0 | BK10: =IF(((AP10+AQ10)-BJ10)>BE10,BE10,(AP10+AQ10)-BJ10) -> 0.5 | BL10: =IF((AP10+AQ10-BJ10-BK10)>=BF10,BF10,(AP10+AQ10-BJ10-BK10)) -> 1.5 | BM10: =IF((AP10+AQ10-BJ10-BK10-BL10)>=BG10,BG10,(AP10+AQ10-BJ10-BK10-BL10)) -> 0 | BN10: =AS10 -> 0 | BO10: =AP10+AQ10-BJ10-BK10-BL10-BM10 -> 0 | BP10: =BD10-BJ10 -> 0 | BQ10: =BE10-BK10 -> 0 | BR10: =BF10-BL10 -> 0.5 | BS10: =BG10-BM10 -> 13 | BT10: =BH10-BN10 -> 15 | BU10: =BI10 -> 0.75 | BW10: 01st feb Weekoff taken early in Jan'26
A11: 8 | B11: JAI-494 | D11: Manappuram/Muthoot/Bajaj | E11: KYC | F11: Birdman | G11: Uppal | H11: 9032615583 | I11: srilekha.dodla@jukshio.com | J11: 44845 | L11: W/O | M11: P | N11: P | O11: P | P11: P | Q11: P | R11: P | S11: W/O | T11: W/O | U11: P | V11: P | W11: P | X11: P | Y11: P | Z11: P | AA11: P | AB11: P | AC11: P | AD11: P | AE11: P | AF11: P | AG11: W/O | AH11: P | AI11: P | AJ11: P | AK11: P | AL11: P | AM11: P | AN11: =COUNTIF(L11:AM11,"P")+COUNTIF(L11:AM11,"HFL")/2 -> 24 | AO11: =COUNTIF(L11:AM11,"W/O") -> 4 | AP11: =COUNTIF(L11:AM11,"L") -> 0 | AQ11: =COUNTIF(L11:AM11,"HFL")/2 -> 0 | AR11: =COUNTIF(L11:AM11,"H") -> 0 | AS11: =COUNTIF(L11:AM11,"MG") -> 0 | AT11: =COUNTIF(L11:AM11,"ML") -> 0 | AU11: =COUNTIF(L11:AM11,"UL") -> 0 | AV11: =COUNTIF(L11:AM11,"MC") -> 0 | AW11: =COUNTIF(L11:AM11,"BL") -> 0 | AX11: =COUNTIF(L11:AM11,"MDL") -> 0 | AY11: =COUNTIF(L11:AM11,"LOP") -> 0 | AZ11: =SUM(AN11:AY11) -> 28 | BA11: =SUM(AP11:AQ11,AS11:AY11,AN11) -> 24 | BB11: =AZ11-(AU11+BO11) -> 28 | BC11: =AN11/BA11 -> 1 | BD11: =VLOOKUP(B11,'Jan''26- Leave Bal'!$B$3:$D$83,3,0) -> 0 | BE11: =VLOOKUP(B11,'Jan''26- Leave Bal'!$B$3:$E$83,4,0)+$BE$3 -> 1 | BF11: =VLOOKUP(B11,'Jan''26- Leave Bal'!$B$3:$F$83,5,0)+$BF$3 -> 1.5 | BG11: =VLOOKUP(B11,'Jan''26- Leave Bal'!$B$3:$G$83,6,0)+$BG$3 -> 9.3 | BH11: =VLOOKUP(B11,'Jan''26- Leave Bal'!$B$3:$H$83,7,0) -> 15 | BI11: =VLOOKUP(B11,'Jan''26- Leave Bal'!$B$3:$I$83,8,0)+$BI$3 -> 0.75 | BJ11: =IF((AP11+AQ11)<=BD11, (AP11+AQ11),BD11) -> 0 | BK11: =IF(((AP11+AQ11)-BJ11)>BE11,BE11,(AP11+AQ11)-BJ11) -> 0 | BL11: =IF((AP11+AQ11-BJ11-BK11)>=BF11,BF11,(AP11+AQ11-BJ11-BK11)) -> 0 | BM11: =IF((AP11+AQ11-BJ11-BK11-BL11)>=BG11,BG11,(AP11+AQ11-BJ11-BK11-BL11)) -> 0 | BN11: =AS11 -> 0 | BO11: =AP11+AQ11-BJ11-BK11-BL11-BM11 -> 0 | BP11: =BD11-BJ11 -> 0 | BQ11: =BE11-BK11 -> 1 | BR11: =BF11-BL11 -> 1.5 | BS11: =BG11-BM11 -> 9.3 | BT11: =BH11-BN11 -> 15 | BU11: =BI11 -> 0.75 | BW11: 0
A12: 9 | B12: JAI-1153 | D12: Manappuram/Muthoot/Bajaj | E12: KYC | F12: Birdman | G12: Uppal | H12: 9573067930 | I12: vaishnavi.madoori@jukshio.com | J12: 45086 | L12: W/O | M12: P | N12: P | O12: L | P12: P | Q12: L | R12: W/O | S12: P | T12: L | U12: L | V12: P | W12: P | X12: L | Y12: P | Z12: W/O | AA12: L | AB12: L | AC12: P | AD12: P | AE12: P | AF12: L | AG12: W/O | AH12: P | AI12: P | AJ12: P | AK12: P | AL12: P | AM12: W/O | AN12: =COUNTIF(L12:AM12,"P")+COUNTIF(L12:AM12,"HFL")/2 -> 15 | AO12: =COUNTIF(L12:AM12,"W/O") -> 5 | AP12: =COUNTIF(L12:AM12,"L") -> 8 | AQ12: =COUNTIF(L12:AM12,"HFL")/2 -> 0 | AR12: =COUNTIF(L12:AM12,"H") -> 0 | AS12: =COUNTIF(L12:AM12,"MG") -> 0 | AT12: =COUNTIF(L12:AM12,"ML") -> 0 | AU12: =COUNTIF(L12:AM12,"UL") -> 0 | AV12: =COUNTIF(L12:AM12,"MC") -> 0 | AW12: =COUNTIF(L12:AM12,"BL") -> 0 | AX12: =COUNTIF(L12:AM12,"MDL") -> 0 | AY12: =COUNTIF(L12:AM12,"LOP") -> 0 | AZ12: =SUM(AN12:AY12) -> 28 | BA12: =SUM(AP12:AQ12,AS12:AY12,AN12) -> 23 | BB12: =AZ12-(AU12+BO12) -> 26.5 | BC12: =AN12/BA12 -> 0.65217391 | BD12: =VLOOKUP(B12,'Jan''26- Leave Bal'!$B$3:$D$83,3,0) -> 0 | BE12: =VLOOKUP(B12,'Jan''26- Leave Bal'!$B$3:$E$83,4,0)+$BE$3 -> 0.5 | BF12: =VLOOKUP(B12,'Jan''26- Leave Bal'!$B$3:$F$83,5,0)+$BF$3 -> 0.5 | BG12: =VLOOKUP(B12,'Jan''26- Leave Bal'!$B$3:$G$83,6,0)+$BG$3 -> 5.5 | BH12: =VLOOKUP(B12,'Jan''26- Leave Bal'!$B$3:$H$83,7,0) -> 15 | BI12: =VLOOKUP(B12,'Jan''26- Leave Bal'!$B$3:$I$83,8,0)+$BI$3 -> 0.75 | BJ12: =IF((AP12+AQ12)<=BD12, (AP12+AQ12),BD12) -> 0 | BK12: =IF(((AP12+AQ12)-BJ12)>BE12,BE12,(AP12+AQ12)-BJ12) -> 0.5 | BL12: =IF((AP12+AQ12-BJ12-BK12)>=BF12,BF12,(AP12+AQ12-BJ12-BK12)) -> 0.5 | BM12: =IF((AP12+AQ12-BJ12-BK12-BL12)>=BG12,BG12,(AP12+AQ12-BJ12-BK12-BL12)) -> 5.5 | BN12: =AS12 -> 0 | BO12: =AP12+AQ12-BJ12-BK12-BL12-BM12 -> 1.5 | BP12: =BD12-BJ12 -> 0 | BQ12: =BE12-BK12 -> 0 | BR12: =BF12-BL12 -> 0 | BS12: =BG12-BM12 -> 0 | BT12: =BH12-BN12 -> 15 | BU12: =BI12 -> 0.75 | BV12: 01st Mar weekoff taken in Feb Last week itself | BW12: 0
